Workbook

Sheet READ ME FIRST
A1: SARAMIN VN — TEST CASES · FILE 2 of 2 · ADMIN / SALES → LIVE JOB
A3: This workbook follows one business chain from end to end: define a product, create the customer company, quote them, move the deal, issue the PO, issue the VAT invoice, watch the products land on the company, post a job, and see that job on the jobseeker site.
A4: File 1 (Jobseeker) covers the other side: sign up, CV, applying.
A5: THE MOST IMPORTANT RULE IN THIS WHOLE FILE: nothing is delivered until the VAT INVOICE is issued. A quotation delivers nothing. A PO delivers nothing — it is only the 'we won it' moment. The invoice is what puts products and quota on the company, and it does so immediately. If you ever see quota appear before the invoice, that is a serious bug.
A6: Several tests need two or three people signed in at once (a Sales user, a Kế toán user, a Company user, and a jobseeker). Arrange that before you start — it will save you a lot of time.
A7: Some tests need dates in the past or in the future (72-hour title lock, month-end expiry, activation windows). Ask a developer to prepare back-dated test data or to move the server date; do not wait real days.
A8: Start with the AD-10 End-to-end sheet if you want to understand the whole flow first, then come back and test each screen in detail.
A10: WHAT IS IN EACH SHEET
A11: SUMMARY | B11: Counts Pass / Fail / Blocked / Not Run automatically from every sheet. You never type in it.
A12: AD-01 Create product | B12: The catalogue: SKU, price, VAT, what the buyer receives, activation window, versioning.
A13: AD-02 Create company | B13: Creating a customer in the CRM: company ID, tax-code duplicate checks, parent / subsidiary links, global search.
A14: AD-03 Quotation | B14: Building a quotation with 1–3 options, automatic discounts, sending it, revising it, month-end expiry.
A15: AD-04 Sales pipeline | B15: Moving a deal between stages, the rot / idle colours, closing as Lost with a reason.
A16: AD-05 Issue PO | B16: Turning the accepted option into a PO — and proving it provisions nothing.
A17: AD-06 Issue invoice | B17: The VAT e-invoice: who may issue it, what it triggers, cancelling and re-issuing.
A18: AD-07 Products on company | B18: The products and quota appearing on Company detail, and being spent by posting and unlocking.
A19: AD-08 Create job | B19: The job form on both Admin and the Company site, including the 72-hour title lock.
A20: AD-09 Job on JS site | B20: Proving the job really appears for jobseekers on the homepage, in search and on the job detail.
A21: AD-10 End-to-end | B21: One numbered run through the entire chain. Do these 12 in order, in one sitting.
A22: BUG LOG | B22: One row per failed test case. Delete the grey example row before you start.
A24: WORDS YOU WILL SEE (plain English)
A25: HQ / Admin | B25: Saramin's own staff working in the Admin site.
A26: Sales | B26: The rep who creates companies, quotations and POs.
A27: Kế toán / Accounting | B27: The only role allowed to issue or cancel a VAT invoice, and to confirm money against the bank.
A28: Company / employer user | B28: The customer's own HR person, who posts jobs and reads applications.
A29: Quotation (Báo giá) | B29: The priced offer sent to the customer. Can hold 1–3 options; the customer picks ONE.
A30: Option | B30: One priced alternative inside a quotation. Options are never added together.
A31: PO (Purchase order) | B31: The order document created from the ONE accepted option. It is the 'won' moment — but it delivers nothing.
A32: VAT e-invoice | B32: The legal tax document. Issuing it closes the deal AND releases the products immediately.
A33: Provisioning | B33: The moment a product line becomes usable quota on the customer's account. It happens on the invoice, and only then.
A34: Quota / entitlement | B34: What the company can actually use: job-posting slots and CV unlocks.
A35: Activation window | B35: How long the buyer has to START using what they bought, counted from the invoice date. Usually 12 months.
A36: Customer status | B36: New (never bought) → Existing (has been invoiced) → Churn (no new order for 12 months).
... A40: Entitlement source | B40: 'Requires purchase' = must come from a PO line. 'Always available' = the Admin-only free tier, no PO, no limit.
A42: HOW TO RUN A TEST CASE
A43: 1. Read the Pre-condition | B43: This is what must already be true before you start. If you cannot set it up, put Blocked in Status and say why.
A44: 2. Do the Test Steps in order | B44: Do not skip a step and do not do them out of order. Each numbered line is one action.
A45: 3. Use the Test Data given | B45: If a value is not given, use anything sensible, then write what you used in Notes.
A46: 4. Compare with Expected Result | B46: Every sentence in Expected Result must be true. If even one is not true, the test Fails.
A47: 5. Fill the yellow columns | B47: Actual Result = what really happened. Status = Pass / Fail / Blocked / Not Run. Add your name and the date.
...

Sheet SUMMARY
A1: Test execution summary
A2: Type Pass / Fail / Blocked / Not Run in the Status column of each sheet — these numbers update by themselves. '% Executed' means how many cases you have actually run (Pass + Fail + Blocked).
A4: Sheet | B4: Total cases | C4: Pass | D4: Fail | E4: Blocked | F4: Not Run | G4: % Executed
A5: AD-01 Create product | B5: 20 | C5: =COUNTIF('AD-01 Create product'!K:K,"Pass") | D5: =COUNTIF('AD-01 Create product'!K:K,"Fail") | E5: =COUNTIF('AD-01 Create product'!K:K,"Blocked") | F5: =COUNTIF('AD-01 Create product'!K:K,"Not Run") | G5: =IFERROR((C5+D5+E5)/B5,0)
A6: AD-02 Create company | B6: 28 | C6: =COUNTIF('AD-02 Create company'!K:K,"Pass") | D6: =COUNTIF('AD-02 Create company'!K:K,"Fail") | E6: =COUNTIF('AD-02 Create company'!K:K,"Blocked") | F6: =COUNTIF('AD-02 Create company'!K:K,"Not Run") | G6: =IFERROR((C6+D6+E6)/B6,0)
A7: AD-03 Quotation | B7: 34 | C7: =COUNTIF('AD-03 Quotation'!K:K,"Pass") | D7: =COUNTIF('AD-03 Quotation'!K:K,"Fail") | E7: =COUNTIF('AD-03 Quotation'!K:K,"Blocked") | F7: =COUNTIF('AD-03 Quotation'!K:K,"Not Run") | G7: =IFERROR((C7+D7+E7)/B7,0)
A8: AD-04 Sales pipeline | B8: 22 | C8: =COUNTIF('AD-04 Sales pipeline'!K:K,"Pass") | D8: =COUNTIF('AD-04 Sales pipeline'!K:K,"Fail") | E8: =COUNTIF('AD-04 Sales pipeline'!K:K,"Blocked") | F8: =COUNTIF('AD-04 Sales pipeline'!K:K,"Not Run") | G8: =IFERROR((C8+D8+E8)/B8,0)
A9: AD-05 Issue PO | B9: 16 | C9: =COUNTIF('AD-05 Issue PO'!K:K,"Pass") | D9: =COUNTIF('AD-05 Issue PO'!K:K,"Fail") | E9: =COUNTIF('AD-05 Issue PO'!K:K,"Blocked") | F9: =COUNTIF('AD-05 Issue PO'!K:K,"Not Run") | G9: =IFERROR((C9+D9+E9)/B9,0)
A10: AD-06 Issue invoice | B10: 18 | C10: =COUNTIF('AD-06 Issue invoice'!K:K,"Pass") | D10: =COUNTIF('AD-06 Issue invoice'!K:K,"Fail") | E10: =COUNTIF('AD-06 Issue invoice'!K:K,"Blocked") | F10: =COUNTIF('AD-06 Issue invoice'!K:K,"Not Run") | G10: =IFERROR((C10+D10+E10)/B10,0)
A11: AD-07 Products on company | B11: 14 | C11: =COUNTIF('AD-07 Products on company'!K:K,"Pass") | D11: =COUNTIF('AD-07 Products on company'!K:K,"Fail") | E11: =COUNTIF('AD-07 Products on company'!K:K,"Blocked") | F11: =COUNTIF('AD-07 Products on company'!K:K,"Not Run") | G11: =IFERROR((C11+D11+E11)/B11,0)
A12: AD-08 Create job | B12: 34 | C12: =COUNTIF('AD-08 Create job'!K:K,"Pass") | D12: =COUNTIF('AD-08 Create job'!K:K,"Fail") | E12: =COUNTIF('AD-08 Create job'!K:K,"Blocked") | F12: =COUNTIF('AD-08 Create job'!K:K,"Not Run") | G12: =IFERROR((C12+D12+E12)/B12,0)
A13: AD-09 Job on JS site | B13: 16 | C13: =COUNTIF('AD-09 Job on JS site'!K:K,"Pass") | D13: =COUNTIF('AD-09 Job on JS site'!K:K,"Fail") | E13: =COUNTIF('AD-09 Job on JS site'!K:K,"Blocked") | F13: =COUNTIF('AD-09 Job on JS site'!K:K,"Not Run") | G13: =IFERROR((C13+D13+E13)/B13,0)
A14: AD-10 End-to-end | B14: 12 | C14: =COUNTIF('AD-10 End-to-end'!K:K,"Pass") | D14: =COUNTIF('AD-10 End-to-end'!K:K,"Fail") | E14: =COUNTIF('AD-10 End-to-end'!K:K,"Blocked") | F14: =COUNTIF('AD-10 End-to-end'!K:K,"Not Run") | G14: =IFERROR((C14+D14+E14)/B14,0)
A15: TOTAL | B15: =SUM(B5:B14) | C15: =SUM(C5:C14) | D15: =SUM(D5:D14) | E15: =SUM(E5:E14) | F15: =SUM(F5:F14) | G15: =IFERROR((C15+D15+E15)/B15,0)

Sheet AD-01 Create product
A1: AD-01 · Products catalogue — create, price, activate a sellable product
A2: Fill in only the yellow columns: Actual Result, Status, Tested By, Test Date, Notes / Bug ID. Status must be one of: Pass, Fail, Blocked, Not Run. If a step does not behave as written in 'Expected Result', mark Fail and write exactly what happened.
A3: Test Case ID | B3: Feature / Screen | C3: Test Case Title | D3: Type | E3: Priority | F3: Pre-condition | G3: Test Steps (do these in order) | H3: Test Data | I3: Expected Result (what you should see) | J3: Actual Result | K3: Status | L3: Tested By | M3: Test Date | N3: Notes / Bug ID
A4: AD-01-01 | B4: Products list | C4: The products list opens with the right filters and columns | D4: Positive | E4: High | F4: You are signed in to Admin with a role that can manage products. | G4: 1. Go to Admin → Products. 2. Look at the filters above the list. 3. Look at the columns of the list. | H4: - | I4: There is a Type filter as a DROPDOWN (Posting tier, Placement booking, Credit pack, Add-on, Manual service) and a Status filter as a dropdown (Active, Inactive) — you can use both at the same time. Each row shows: SKU, name, type, price (₫), what it gives the buyer, validity, status and sold count. The product NAME is a link; the SKU is plain text.
A5: AD-01-02 | B5: Create product | C5: Create a job-posting tier product | D5: Positive | E5: High | F5: You are on Admin → Products. | G5: 1. Click to create a new product. 2. Choose Type = Posting tier. 3. Fill SKU: JOB-TEST01. 4. Fill the Vietnamese name and the English name. 5. Set list price 2,710,000 ₫, unit = per job, VAT 8%. 6. Set quota = 10 slots, posting tier = Basic, validity = 30 days, activation window = 12 months. 7. Save. | H5: SKU: JOB-TEST01 VI name: Tin đăng Basic (Test) EN name: Basic Job (Test) Price: 2,710,000 | I5: The product is saved. It is created as Inactive (not sellable yet). Everything you typed is shown correctly when you re-open it.
A6: AD-01-03 | B6: Create product | C6: Choosing a type only shows the fields that type needs | D6: Positive | E6: High | F6: You are creating a new product. | G6: 1. Choose Type = Posting tier and note the fulfilment fields shown. 2. Change to Credit pack and note the fields. 3. Change to Placement booking. 4. Change to Add-on. 5. Change to Manual service. | H6: - | I6: Posting tier asks for slots, tier and validity. Credit pack asks for CV unlocks and 30/90-day validity. Placement asks for a placement from the registry and a booking unit. Add-on asks what it attaches to and its capacity. Manual service asks for SLA days, owning team and required inputs. No screen shows fields that do not apply to its type.
A7: AD-01-04 | B7: Create product | C7: A duplicate SKU is refused | D7: Negative | E7: High | F7: The product JOB-TEST01 already exists. | G7: 1. Create a new product with SKU = JOB-TEST01. 2. Save. | H7: SKU: JOB-TEST01 | I7: The save is refused with a message saying the SKU is already used. No second product is created.
A8: AD-01-05 | B8: Create product | C8: The Vietnamese name is required; the English one prints on the quotation | D8: Negative | E8: Medium | F8: You are creating a new product. | G8: 1. Leave the Vietnamese name empty and try to save. 2. Fill VI, leave EN empty, and save. 3. Add the product to a quotation and generate the PDF. | H8: - | I8: The save is refused with no Vietnamese name. It saves with no English name. On the bilingual quotation PDF, the English name is what appears in the English column — if it is missing, note what the PDF prints instead.
A9: AD-01-06 | B9: Activation window | C9: Activation window defaults to 12 months and offers 3 / 6 / 12 / 18 / 24 | D9: Positive | E9: High | F9: You are creating a posting-tier product. | G9: 1. Look at the 'activation window' field before touching it. 2. Open its list of choices. | H9: - | I9: It defaults to 12 months (the client's T&C clause 4). The only choices are 3, 6, 12, 18 and 24 months. It sits on the PRODUCT — it is not a single global setting.
A10: AD-01-07 | B10: Activation window | C10: Two different products can carry two different activation windows | D10: Positive | E10: High | F10: You can create two products. | G10: 1. Create a paid Top Job product with a 12-month activation window. 2. Create a trial posting product with a 3-month activation window. 3. Save both and re-open them. | H10: - | I10: Each product keeps its own window. Setting one does not change the other.
A11: AD-01-08 | B11: Create product | C11: A product marked 'Always available' needs no price | D11: Edge | E11: High | F11: You are creating a job-posting product. | G11: 1. Set entitlementSource = Always available (the Admin-only free tier). 2. Leave the list price empty. 3. Save and activate it. | H11: - | I11: The product saves and activates with no price. No activation window is asked for either — this tier is never invoiced, so there is no invoice date to count from.
A12: AD-01-09 | B12: Create product | C12: A product marked 'Requires purchase' must have a price | D12: Negative | E12: High | F12: You are creating a job-posting product. | G12: 1. Set entitlementSource = Requires purchase. 2. Leave the list price empty. 3. Try to activate it. | H12: - | I12: Activation is refused until a price is set.
A13: AD-01-10 | B13: Create product | C13: An add-on with nothing to attach to cannot be sold | D13: Negative | E13: High | F13: You are creating an Add-on product. | G13: 1. Leave 'attaches to' empty. 2. Try to activate the product. 3. If it activates, open a quotation and try to add it as a standalone line. | H13: - | I13: Either activation is refused, or the add-on can never be added to a quotation on its own. An add-on with no parent tier must not be sellable.
A14: AD-01-11 | B14: Create product | C14: A placement product must point at a real placement in the registry | D14: Negative | E14: High | F14: The Placements registry has at least one row. | G14: 1. Create a Placement booking product. 2. Try to save it WITHOUT choosing a placement. 3. Choose a placement and look at the size / items shown / rotation. | H14: - | I14: It cannot be activated without a placement from the registry. Once chosen, the size and the number of items shown are READ from that row and cannot be re-typed here.
A15: AD-01-12 | B15: Activation | C15: A product with an incomplete definition cannot be activated | D15: Negative | E15: High | F15: You have a posting-tier product with no quota / validity filled in. | G15: 1. Try to activate it. 2. Read the message. | H15: - | I15: Activation is blocked, and the message names exactly what is missing. A product must say clearly what the buyer receives before it can be sold.
... A23: AD-01-20 | B23: Create product | C23: Every product must declare a VAT rate | D23: Negative | E23: High | F23: You are creating a product. | G23: 1. Leave the VAT rate empty. 2. Try to save / activate. | H23: - | I23: It cannot be activated without a VAT rate — otherwise the quotation and the VAT invoice could disagree with each other.

Sheet AD-02 Create company
A1: AD-02 · CRM Companies — create a customer, company ID, tax code checks
A2: Fill in only the yellow columns: Actual Result, Status, Tested By, Test Date, Notes / Bug ID. Status must be one of: Pass, Fail, Blocked, Not Run. If a step does not behave as written in 'Expected Result', mark Fail and write exactly what happened.
A3: Test Case ID | B3: Feature / Screen | C3: Test Case Title | D3: Type | E3: Priority | F3: Pre-condition | G3: Test Steps (do these in order) | H3: Test Data | I3: Expected Result (what you should see) | J3: Actual Result | K3: Status | L3: Tested By | M3: Test Date | N3: Notes / Bug ID
A4: AD-02-01 | B4: New company | C4: '+ New company' opens a full page with four sections | D4: Positive | E4: High | F4: You are signed in to Admin as a sales user. | G4: 1. Go to CRM → Companies. 2. Click '+ New company'. 3. Look at the page. | H4: - | I4: A full page opens (not a small pop-up dialog), and the URL can be copied and reloaded. There are four sections in this order: Company information, Company verification document, Primary contact, Sales.
A5: AD-02-02 | B5: New company | C5: Create a company with everything required filled in | D5: Positive | E5: High | F5: You are on the New company page. | G5: 1. Fill Legal name and Tax code (MST). 2. Pick country Việt Nam and a province, and type an address. 3. Fill the Primary contact: name, phone and email. 4. Click Save. | H5: Legal name: CÔNG TY TNHH TEST QA MST: 0301234599 Contact: Tran Thi B, 0909111222, b.test@mail.com | I5: The company is created and its detail page opens. Customer status is 'New' (they have never bought anything). Pipeline status is 'Not in pipeline' (no deal yet).
A6: AD-02-03 | B6: New company | C6: Legal name and tax code are required | D6: Negative | E6: High | F6: You are on the New company page. | G6: 1. Leave Legal name empty, fill everything else, and save. 2. Fill Legal name, clear the Tax code, and save. | H6: - | I6: Both saves are refused, each naming the missing field. The rest of what you typed stays on screen.
A7: AD-02-04 | B7: New company | C7: The primary contact needs BOTH a phone and an email | D7: Negative | E7: High | F7: You are on the New company page. | G7: 1. Fill everything, but leave the contact phone empty. Save. 2. Fill the phone, clear the contact email. Save. | H7: - | I7: Both saves are refused. A contact must have both channels — one is not enough when the other bounces.
A8: AD-02-05 | B8: Company ID | C8: A company ID is created on save, in the format CO-XXXXXXX | D8: Positive | E8: High | F8: You just created a company. | G8: 1. Look at the New company FORM before saving — is there a Company ID field? 2. Save. 3. Look at the company detail header, at the Basic info card, and at the URL. | H8: - | I8: There is NO Company ID box on the form (you cannot fill it, so it is not shown). After saving, an ID like CO-P9FCEPD appears in the header, in the first row of Basic info, and in the URL.
A9: AD-02-06 | B9: Company ID | C9: The company ID never changes | D9: Edge | E9: High | F9: A company exists with a known ID. | G9: 1. Write down the ID. 2. Edit the legal name, the tax code and the sales owner. Save. 3. Check the ID again. | H9: - | I9: The ID is exactly the same. There is no way to edit it anywhere in the UI.
A10: AD-02-07 | B10: Company ID | C10: Searching by company ID is forgiving about how you type it | D10: Positive | E10: High | F10: A company with ID CO-Y2FKY36 exists (use your own real ID). | G10: 1. Search the full ID with the CO- prefix. 2. Search it in small letters with no prefix (y2fky36). 3. Search it typing the letter O instead of the digit 0, if the ID contains a 0. | H10: The real ID of your test company | I10: All three searches find the same company. The prefix is optional, capitals do not matter, and O/0 and I/L/1 are treated as the same.
A11: AD-02-08 | B11: Company ID | C11: A mistyped company ID does NOT open a different company | D11: Negative | E11: High | F11: A company with a known ID exists. | G11: 1. Take the real ID and change the LAST character to something else. 2. Search for it. | H11: A deliberately wrong last character | I11: Nothing is found, or an 'invalid ID' message is shown. A wrong ID must NEVER open some other company's record.
A12: AD-02-09 | B12: Tax code | C12: An identical full tax code blocks the save | D12: Negative | E12: High | F12: A company already exists with MST 0301234599. | G12: 1. Start a new company and type the same MST 0301234599. 2. Fill the rest and save. | H12: MST: 0301234599 | I12: The save is BLOCKED. The error names the existing company and gives a link to open it. No duplicate company is created.
A13: AD-02-10 | B13: Tax code | C13: A shared 10-digit root is NOT blocked — it offers a link instead | D13: Edge | E13: High | F13: A company exists with MST 0301234599. | G13: 1. Start a new company and type MST 0301234599-001. 2. Fill the rest of the form. 3. Read what appears under the tax code field. 4. Save without linking anything. | H13: MST: 0301234599-001 | I13: The save is NOT blocked. A list of companies on the same 10-digit root appears, each showing name, full MST, location and sales owner, badged 'cùng gốc MST'. Linking is offered but optional — saving without linking creates a normal standalone company.
A14: AD-02-11 | B14: Tax code | C14: A near-identical name on a different tax code also offers a link, and does not block | D14: Edge | E14: Medium | F14: A company 'CÔNG TY TNHH TEST QA' exists. | G14: 1. Create 'CÔNG TY TNHH TEST QA MIỀN NAM' with a completely different MST. 2. Read what the form shows. 3. Save. | H14: A different MST, a similar name | I14: The similar company is listed as a possible affiliate. The save is not blocked.
A15: AD-02-12 | B15: Company links | C15: 'Là con của' can only be set on one row; 'Là mẹ của' can be set on many | D15: Edge | E15: Medium | F15: The affiliate list is showing at least 3 companies. | G15: 1. Click '↑ Là con của' on row 1, then on row 2. 2. Click '↓ Là mẹ của' on rows 1, 2 and 3. 3. Read the running summary line. | H15: - | I15: Choosing 'Là con của' on row 2 releases it from row 1 — only ONE parent is possible. 'Là mẹ của' stays selected on all three rows at once. A summary line states the result in words, for example 'Sẽ liên kết: công ty con của X, công ty mẹ của Y, Z'.
... A31: AD-02-28 | B31: Company detail | C31: A company owned by another rep opens read-only | D31: Negative | E31: High | F31: A company is owned by a different sales rep. | G31: 1. Open it through the global search. 2. Try to edit the Basic info card. 3. Try to change the pipeline stage badge. | H31: - | I31: The record opens (reaching it is a read, not a takeover). Editing is not possible and the reason is shown. Ownership does not change just because you opened it.

Sheet AD-03 Quotation
A1: AD-03 · Quotation (Báo giá) — build, discount, send, revise, expire
A2: Fill in only the yellow columns: Actual Result, Status, Tested By, Test Date, Notes / Bug ID. Status must be one of: Pass, Fail, Blocked, Not Run. If a step does not behave as written in 'Expected Result', mark Fail and write exactly what happened.
A3: Test Case ID | B3: Feature / Screen | C3: Test Case Title | D3: Type | E3: Priority | F3: Pre-condition | G3: Test Steps (do these in order) | H3: Test Data | I3: Expected Result (what you should see) | J3: Actual Result | K3: Status | L3: Tested By | M3: Test Date | N3: Notes / Bug ID
A4: AD-03-01 | B4: Create quotation | C4: Opening 'Create quotation' from a company pre-selects that company | D4: Positive | E4: High | F4: You are on a company detail page. | G4: 1. Click 'Tạo báo giá / Create quotation'. 2. Look at the company field. | H4: - | I4: The company is already chosen and the quotation is attached to that company and its deal. A quotation is never left floating with no company.
A5: AD-03-02 | B5: Create quotation | C5: Opening it from the Quotations list asks which company | D5: Positive | E5: Medium | F5: You are on CRM → Quotations. | G5: 1. Click Create quotation from the list title row. | H5: - | I5: You are asked to choose a company before you can continue.
A6: AD-03-03 | B6: Quotation header | C6: The quotation number is generated and cannot be edited | D6: Positive | E6: High | F6: You are creating a quotation in July 2026. | G6: 1. Look at the quotation code. 2. Try to click into it and change it. | H6: - | I6: It reads QUO-{6 digits}-{MM}-{YYYY}, for example QUO-009909-07-2026. It cannot be edited. The next quotation you create has the next number in sequence.
A7: AD-03-04 | B7: Quotation header | C7: The expiry date is always the last day of the month | D7: Positive | E7: High | F7: You can create quotations on different dates (ask a developer to change the server date if needed). | G7: 1. Create a quotation on the 5th of the month and note the expiry date. 2. Create one on the 28th of the same month and note the expiry date. 3. Try to type a different expiry date. | H7: - | I7: BOTH show the last day of that month, for example 31/07/2026 — not 14 or 30 days after sending. The date cannot be typed by hand.
A8: AD-03-05 | B8: Quotation header | C8: The letterhead comes from settings, never typed per quotation | D8: Positive | E8: High | F8: You can open System → Company information. | G8: 1. Create a quotation and look at the issuer block (logo, VN + EN legal name, VN + EN address, website). 2. Try to edit any of it on the quotation. 3. Ask an admin to change the website in System → Company information. 4. Create a NEW quotation and check the website. 5. Re-open an OLD sent quotation and check its website. | H8: - | I8: The issuer block cannot be typed on the quotation — it comes from settings. A new quotation picks up the changed value. An already-sent quotation still prints the OLD value — old documents must reprint identically.
A9: AD-03-06 | B9: Quotation header | C9: 'Proposed by' is the signed-in rep | D9: Positive | E9: Medium | F9: You are signed in as a known sales user. | G9: 1. Create a quotation and read the 'Báo giá bởi / Proposed by' line. | H9: - | I9: It shows your own name and email — it is not a field you pick.
A10: AD-03-07 | B10: Client & billing | C10: Client and billing details are pre-filled from the company record | D10: Positive | E10: High | F10: The company has a primary contact and billing details. | G10: 1. Create a quotation for it. 2. Look at the Client information block and the VAT billing block. | H10: - | I10: Client name, email and phone are pre-filled from the primary contact. Billing company name, registered address and tax code are pre-filled from the company record. You only edit what is different.
A11: AD-03-08 | B11: Client & billing | C11: The 'same as company' toggle copies across and writes back | D11: Positive | E11: Medium | F11: You are on the billing block of a new quotation. | G11: 1. Turn on 'same as company'. 2. Change the billing address on the quotation. 3. Save the quotation. 4. Open the company record and look at the address. | H11: - | I11: The details copy across in one click. The edit you made writes back to the company record — you do not have to update it in two places.
A12: AD-03-09 | B12: Options | C12: A quotation can hold 1 to 3 options and no more | D12: Negative | E12: High | F12: You are building a quotation. | G12: 1. Add option 1 with a product line. 2. Add option 2. 3. Add option 3. 4. Try to add option 4. | H12: - | I12: Three options can be created. The 4th is refused.
A13: AD-03-10 | B13: Options | C13: Each option totals on its own, and there is no grand total | D13: Positive | E13: High | F13: You have a quotation with 2 options at different prices. | G13: 1. Look at option 1: subtotal, VAT and total after VAT. 2. Look at option 2: the same three numbers. 3. Look for any number adding the two options together, on screen and on the PDF. | H13: Option 1: 6,588,000 Option 2: 2,926,800 | I13: Each option carries its own subtotal, VAT and total after VAT. There is NO grand total anywhere — options are alternatives, not things you add up. If you find 9,514,800 printed anywhere, mark Fail.
A14: AD-03-11 | B14: Options | C14: Adding a product pulls its name, unit, price and benefits from the catalogue | D14: Positive | E14: High | F14: An Active product with a benefit list exists. | G14: 1. Add that product as a line in an option. 2. Look at the line: name, unit, unit price. 3. Look at the 'Quyền lợi gói' benefit section of the option. | H14: - | I14: The VI and EN names, the unit and the list price all come from the product. The benefit list is composed from the catalogue — nobody types it.
A15: AD-03-12 | B15: Options | C15: The line total is calculated, not typed | D15: Positive | E15: High | F15: You have a line in an option. | G15: 1. Set quantity 3 and unit price 2,000,000. 2. Set a discount of 25%. 3. Read the line total. | H15: 3 × 2,000,000, 25% off | I15: The line total reads 4,500,000 (3 × 2,000,000 × 0.75). It is read-only — you cannot type over it.
... A37: AD-03-34 | B37: Status | C37: The quotation has exactly four statuses | D37: Positive | E37: High | F37: You are on the Quotations list. | G37: 1. Open the status filter and read every value. | H37: - | I37: Exactly four: Draft, Sent, Issued to PO, Expired. There is no 'Accepted' status, no 'Awaiting approval' status and no 'Revised' status.

Sheet AD-04 Sales pipeline
A1: AD-04 · Sales pipeline — moving a deal through the stages
A2: Fill in only the yellow columns: Actual Result, Status, Tested By, Test Date, Notes / Bug ID. Status must be one of: Pass, Fail, Blocked, Not Run. If a step does not behave as written in 'Expected Result', mark Fail and write exactly what happened.
A3: Test Case ID | B3: Feature / Screen | C3: Test Case Title | D3: Type | E3: Priority | F3: Pre-condition | G3: Test Steps (do these in order) | H3: Test Data | I3: Expected Result (what you should see) | J3: Actual Result | K3: Status | L3: Tested By | M3: Test Date | N3: Notes / Bug ID
A4: AD-04-01 | B4: Pipeline board | C4: The board shows the stages in the right order | D4: Positive | E4: High | F4: You are signed in to Admin as a sales user with some deals. | G4: 1. Go to CRM → Sales pipeline. 2. Read the column headings from left to right. | H4: - | I4: The columns are Proposal, Qualified, Negotiation, PO, Invoice — matching the document chain. Lost is reachable as a filter / drawer rather than a permanent column.
A5: AD-04-02 | B5: Pipeline board | C5: Each column shows how many deals and how much they are worth | D5: Positive | E5: High | F5: The Proposal column holds 2 deals worth 6,588,000 and 3,000,000. | G5: 1. Read the count and total on the Proposal column. 2. Check the arithmetic yourself. | H5: - | I5: The column reads 2 deals and 9,588,000 ₫. Each deal contributes exactly ONE option's total (the accepted one, otherwise the highest) — never the sum of the options it offered. Only OPEN deals are counted.
A6: AD-04-03 | B6: Deal card | C6: The card shows everything a rep needs at a glance | D6: Positive | E6: Medium | F6: There is at least one deal on the board. | G6: 1. Read one card carefully. | H6: - | I6: It shows the company, its industry, the deal value, the owner, when the last activity was, a health dot (green / amber / red) and badges counting linked quotes / POs / invoices / contracts.
A7: AD-04-04 | B7: Change stage | C7: The stage menu offers only the stages a person may set | D7: Positive | E7: High | F7: You are on the company detail page of a company with an open deal at Proposal. | G7: 1. Click the stage badge in the header. 2. Read every value in the menu. | H7: - | I7: The menu offers Proposal, Qualified, Negotiation and Lost. PO and Invoice are NOT in the menu at all — not even greyed out. They are written by the system. The badge has a chevron inside the chip so you can tell it is clickable.
A8: AD-04-05 | B8: Change stage | C8: Moving between Proposal, Qualified and Negotiation works in both directions | D8: Positive | E8: High | F8: A deal sits at Proposal. | G8: 1. Move it to Qualified. 2. Move it to Negotiation. 3. Move it BACK to Proposal. | H8: - | I8: Every move works, forwards and backwards. This is not a one-way ladder — deals genuinely go backwards when a champion leaves.
A9: AD-04-06 | B9: Close as Lost | C9: Closing as Lost requires a reason | D9: Negative | E9: High | F9: A deal is open at Negotiation. | G9: 1. Choose Lost from the stage badge. 2. Try to save without picking a reason. 3. Pick a reason and save. | H9: Reason: Giá cao / Price | I9: The save is blocked until a reason is chosen. The reasons offered include: lost to competitor, price / over budget, no budget this cycle, no response / went silent, not a fit, internal approval rejected.
A10: AD-04-07 | B10: Close as Lost | C10: Losing a deal does NOT change the customer status | D10: Edge | E10: High | F10: You have one New company and one Existing company, each with an open deal. | G10: 1. Note both customer statuses. 2. Close both deals as Lost with a reason. 3. Check both customer statuses again. 4. Check both companies still exist. | H10: - | I10: New stays New. Existing stays Existing. Both companies still exist, keep their history, and move to the nurture list with no open deal. Pipeline status reads 'Not in pipeline'.
A11: AD-04-08 | B11: Close as Lost | C11: A Lost deal can be re-opened | D11: Positive | E11: Medium | F11: You have a deal closed as Lost. | G11: 1. Open the company and find the deal. 2. Move it back to an earlier stage. | H11: - | I11: The control is still there on a Lost deal and the deal can be re-opened.
A12: AD-04-09 | B12: Terminal stage | C12: A deal that reached Invoice offers no further stage change | D12: Positive | E12: High | F12: A deal reached the Invoice stage (an invoice was issued). | G12: 1. Open the company detail and look at the stage badge. | H12: - | I12: The badge is not editable — the control is not shown at all. Invoice is terminal and closed-won.
A13: AD-04-10 | B13: Rot clock | C13: A deal with no activity turns amber, then red, without moving stage | D13: Edge | E13: High | F13: A deal sits at Proposal (thresholds: amber 7 days, red 21 days). Ask a developer to move the server date, or use pre-aged test data. | G13: 1. Note the deal's stage and colour. 2. Age it past 7 days with no activity — check the colour. 3. Age it past 21 days — check the colour and the 'Needs attention' filter. 4. Check the stage. | H13: - | I13: At 7 days it is amber, at 21 days it is red and it appears in the 'Needs attention' filter. The STAGE never changes and the card never moves by itself.
A14: AD-04-11 | B14: Rot clock | C14: Logging a call or a chat resets the clock | D14: Positive | E14: High | F14: You have a red deal. | G14: 1. Log a call or a chat activity on the deal. 2. Look at the colour. | H14: - | I14: The deal goes back to green immediately.
A15: AD-04-12 | B15: Rot clock | C15: A quote revision and a payment reset the clock without changing the stage | D15: Edge | E15: High | F15: You have one amber deal at Negotiation and one amber deal at PO. | G15: 1. On the Negotiation deal, revise the quotation to v2 and send it. Check the colour and the stage. 2. On the PO deal, record a payment. Check the colour and the stage. | H15: - | I15: Both go green. Neither one changes stage. These are the two document events that are not also stage changes, and they are exactly when a deal is most alive.
... A25: AD-04-22 | B25: Audit | C25: Every stage change is recorded | D25: Positive | E25: High | F25: You changed a deal's stage. | G25: 1. Open the deal / company history. | H25: - | I25: The entry shows from which stage, to which stage, who did it, when, and the reason if there was one.

Sheet AD-05 Issue PO
A1: AD-05 · Purchase order — issue it from the accepted option
A2: Fill in only the yellow columns: Actual Result, Status, Tested By, Test Date, Notes / Bug ID. Status must be one of: Pass, Fail, Blocked, Not Run. If a step does not behave as written in 'Expected Result', mark Fail and write exactly what happened.
A3: Test Case ID | B3: Feature / Screen | C3: Test Case Title | D3: Type | E3: Priority | F3: Pre-condition | G3: Test Steps (do these in order) | H3: Test Data | I3: Expected Result (what you should see) | J3: Actual Result | K3: Status | L3: Tested By | M3: Test Date | N3: Notes / Bug ID
A4: AD-05-01 | B4: Issue PO | C4: 'Issue PO' is only offered on a quotation with an accepted option | D4: Negative | E4: High | F4: You have: (a) a Sent quotation with no option accepted yet, (b) a Sent quotation with an accepted option. | G4: 1. Open quotation (a) and look for 'Issue PO'. 2. Record an accepted option on it. 3. Look again. 4. Open quotation (b) — the action should already be there. | H4: - | I4: Before an option is accepted, Issue PO is not available. After recording the accepted option, it appears on the accepted row. The action lives on the accepted quotation, not on the company header.
A5: AD-05-02 | B5: Issue PO | C5: The PO copies the accepted option exactly | D5: Positive | E5: High | F5: You have a quotation whose accepted option has 2 paid lines and 1 gift line. | G5: 1. Write down the accepted option's lines, quantities, unit prices, discounts, subtotal, VAT and total after VAT. 2. Write down the billing name, address and tax code. 3. Issue the PO. 4. Compare every number and every line on the PO. | H5: - | I5: Every line, quantity, unit price, discount and total on the PO matches the accepted option exactly, gift line included. The billing block is carried across unchanged. Nothing had to be re-typed.
A6: AD-05-03 | B6: Issue PO | C6: Options the customer did NOT choose never appear on the PO | D6: Negative | E6: High | F6: The quotation had 3 options and option 2 was accepted. | G6: 1. Issue the PO. 2. Read every line on it. | H6: - | I6: Only option 2's lines are there. Options 1 and 3 are nowhere on the PO.
A7: AD-05-04 | B7: Issue PO | C7: The PO number follows PO-{6 digits}-{MM}-{YYYY} | D7: Positive | E7: High | F7: You just issued a PO in July 2026. | G7: 1. Read the PO code. 2. Issue another PO and read its code. | H7: - | I7: It reads like PO-005864-07-2026 and the next one is the next number in sequence. It must NOT start with INV- — that prefix belongs to the tax invoice only.
A8: AD-05-05 | B8: Issue PO | C8: A new PO is Active immediately — there is no Draft and no Sent | D8: Positive | E8: High | F8: You just issued a PO. | G8: 1. Look at its status. 2. Open the status filter on the PO list and read every value. | H8: - | I8: The PO is Active straight away. The only statuses that exist are Active, Issued invoice and Expired. There is no Draft, no Sent, no Paid and no Cancelled.
A9: AD-05-06 | B9: Issue PO | C9: Issuing the PO is the 'won' moment — the deal moves to the PO stage | D9: Positive | E9: High | F9: The deal was at Negotiation. | G9: 1. Issue the PO. 2. Open the pipeline board. 3. Check the company's customer status. | H9: - | I9: The deal card moves to the PO column. The customer status is UNCHANGED — a New company is still New, because they have not paid and nothing has been delivered.
A10: AD-05-07 | B10: Issue PO | C10: A PO on its own provisions NOTHING | D10: Negative | E10: High | F10: You just issued a PO for a company that has never bought before. | G10: 1. Open the company detail → Products & billing (Purchased / Quota). 2. Check whether a company account or login exists. 3. Check whether a public company page exists. 4. If a company login exists, sign in and try to post a job. | H10: - | I10: There are NO purchased products and NO quota on the company. No account and no login were created. No company page exists. Nothing can be posted. If ANY quota appears at this point, mark Fail — only the invoice provisions.
A11: AD-05-08 | B11: Issue PO | C11: The PO expires at the end of the month it was issued in | D11: Edge | E11: High | F11: You can issue POs on different dates (move the server date if needed). | G11: 1. Issue a PO on the 5th of the month and read its expiry date. 2. Issue another on the 28th of the same month and read its expiry date. | H11: - | I11: BOTH expire on the last day of that month, for example 31/07. It is never a rolling 30 days.
A12: AD-05-09 | B12: Issue PO | C12: A PO cannot be issued from an expired quotation | D12: Negative | E12: High | F12: You have an Expired quotation that had an accepted option. | G12: 1. Try to issue a PO from it. 2. Ask a developer to POST to the create-order endpoint with that quotation id. | H12: - | I12: Both the screen and the API refuse it. The reason is shown: the commercial terms lapsed with the quotation. Revise to v2 or extend it first.
A13: AD-05-10 | B13: Issue PO | C13: The customer's own PO number and file can be attached without changing anything | D13: Positive | E13: Medium | F13: You have an Active PO. | G13: 1. Note the PO status. 2. Attach the customer's PO number 'PO-VP/2026/044' and upload their signed PO file. 3. Check the status again. | H13: Customer PO no: PO-VP/2026/044 | I13: The number and the file are saved on the PO as evidence. The status is still Active — attaching evidence is not a status change. The customer's number is stored exactly as they wrote it.
A14: AD-05-11 | B14: PO | C14: A PO can never be cancelled | D14: Negative | E14: High | F14: You have an Active PO and an invoiced PO. | G14: 1. Look for a Cancel action on the Active PO. 2. Look for one on the invoiced PO. 3. Ask a developer to call POST /admin/crm/orders/{id}/cancel. | H14: - | I14: There is NO cancel action in any status. The endpoint does not exist at all — the UI is not the only thing preventing it. A sale is undone by cancelling the INVOICE.
A15: AD-05-12 | B15: PO | C15: A PO cannot be edited after it is issued | D15: Negative | E15: High | F15: You have an Active PO. | G15: 1. Try to change a line, a quantity or a price on it. | H15: - | I15: Nothing can be edited. To change what the customer buys, a new PO is issued from a live quotation.
... A19: AD-05-16 | B19: Quotation link | C19: Issuing the PO moves the quotation to 'Issued to PO' | D19: Positive | E19: High | F19: You just issued a PO from a Sent quotation. | G19: 1. Open the source quotation. 2. Look at its status. 3. Look at the PO's 'source quotation' field. | H19: - | I19: The quotation status is 'Issued to PO'. The PO shows the audit link back, for example 'QUO-009909-07-2026 · Option 1'.

Sheet AD-06 Issue invoice
A1: AD-06 · VAT e-invoice — issue, cancel, re-issue (Kế toán only)
A2: Fill in only the yellow columns: Actual Result, Status, Tested By, Test Date, Notes / Bug ID. Status must be one of: Pass, Fail, Blocked, Not Run. If a step does not behave as written in 'Expected Result', mark Fail and write exactly what happened.
A3: Test Case ID | B3: Feature / Screen | C3: Test Case Title | D3: Type | E3: Priority | F3: Pre-condition | G3: Test Steps (do these in order) | H3: Test Data | I3: Expected Result (what you should see) | J3: Actual Result | K3: Status | L3: Tested By | M3: Test Date | N3: Notes / Bug ID
A4: AD-06-01 | B4: Issue invoice | C4: Only an Accounting (Kế toán) user can issue the VAT invoice | D4: Negative | E4: High | F4: You have an Active PO. You can sign in as a Sales user and as a Kế toán user. | G4: 1. Sign in as SALES and look for 'Xuất hóa đơn' on the PO. 2. Ask a developer to POST to the create-invoice endpoint while signed in as Sales. 3. Sign in as KẾ TOÁN and look at the same PO. | H4: - | I4: Sales cannot issue the invoice — the action is not available, and the API returns 403. Kế toán can. The person whose target depends on the deal closing must not be the one who releases the product.
A5: AD-06-02 | B5: Issue invoice | C5: The invoice can be issued even when nothing has been paid | D5: Positive | E5: High | F5: You have an Active PO whose payment state is 'unpaid'. | G5: 1. Sign in as Kế toán. 2. Issue the VAT invoice on that PO. | H5: - | I5: The invoice is issued successfully. A confirmed payment is NOT required — many customers need the invoice in hand before their finance team releases the money. (This is a deliberate deviation from the client's T&C clause 3 — note it in your report.)
A6: AD-06-03 | B6: Issue invoice | C6: The invoice cannot be issued on an Expired PO | D6: Negative | E6: High | F6: You have an Expired PO. | G6: 1. Look at the invoice action on it. 2. Ask a developer to POST to the create-invoice endpoint with that PO id. | H6: - | I6: The action is disabled and says why. The API also refuses — the check is server-side, not just a disabled button.
A7: AD-06-04 | B7: Issue invoice | C7: Issuing is blocked when the billing details do not match the quotation | D7: Negative | E7: High | F7: You have an Active PO. Ask a developer to change the billing tax code on the company after the quotation was snapshotted. | G7: 1. Try to issue the invoice. | H7: - | I7: Issuing is BLOCKED with a message about the mismatch. The details are not silently corrected — they must equal what was snapshotted on the quotation.
A8: AD-06-05 | B8: Issue invoice | C8: Issuing is blocked when the company has no verification document | D8: Negative | E8: High | F8: You have a company with an Active PO and NO verification document on file. | G8: 1. Try to issue the VAT invoice. 2. Upload a business licence. 3. Try again. | H8: - | I8: The first attempt is blocked with a clear reason — this is the point where the tax identity has to be real. After uploading the document, issuing works.
A9: AD-06-06 | B9: Issue invoice | C9: The invoice carries both our number and the provider's legal number | D9: Positive | E9: High | F9: You just issued a VAT invoice. | G9: 1. Read the invoice code on the list and the detail. 2. Download the PDF and the XML. 3. Open the customer's mailbox. | H9: - | I9: Both numbers are shown: our internal INV-{6 digits}-{MM}-{YYYY} and the provider's legal series, for example 1C26TAA/0041. The PDF and XML are stored and can be downloaded. The customer receives them by email.
A10: AD-06-07 | B10: Issue invoice | C10: Issuing closes the deal and flips the customer status | D10: Positive | E10: High | F10: The company's customer status is New and the deal is at the PO stage. | G10: 1. Note the customer status and the pipeline stage. 2. Issue the VAT invoice. 3. Check the pipeline board and the company record again. | H10: - | I10: The deal closes as won and leaves the open board. The customer status changes from New to Existing. This is the ONLY event that writes the customer status.
A11: AD-06-08 | B11: Issue invoice | C11: The 'Activate by' date is the invoice date plus the PRODUCT's own window | D11: Edge | E11: High | F11: You have a PO holding a 12-month product and a 3-month trial product. | G11: 1. Issue the invoice. 2. Read the 'Activate by' / activation deadline for each line. 3. Ask a developer to change the product's activation window afterwards. 4. Re-check the deadline on this invoice. | H11: 12-month product + 3-month trial | I11: Each line has its OWN deadline: invoice date + 12 months, and invoice date + 3 months. Changing the product afterwards does NOT move the deadline on quota already sold — it was snapshotted.
A12: AD-06-09 | B12: Issue invoice | C12: The gift lines print at 0 ₫ and add nothing to VAT | D12: Positive | E12: High | F12: The PO contains a gift '(Tặng)' line. | G12: 1. Issue the invoice. 2. Open the invoice PDF. 3. Check the gift line and the VAT base. | H12: - | I12: The gift line appears at 0 ₫, so the customer has a legal record of what they receive. It contributes nothing to the VAT base — the VAT total matches the paid lines only.
A13: AD-06-10 | B13: Issue invoice | C13: The VAT rate used is the one snapshotted on the quotation | D13: Edge | E13: High | F13: A quotation was sent at 8% VAT. Ask an admin to change the VAT rate in settings to 10% afterwards. | G13: 1. Issue the invoice on that PO. 2. Read the VAT rate on the invoice. | H13: Settings changed 8% → 10% | I13: The invoice prints 8% — the rate the quotation was sent with. A state rate change does not rewrite a document already agreed.
A14: AD-06-11 | B14: Issue invoice | C14: An issued invoice can never be edited | D14: Negative | E14: High | F14: You have an Issued invoice. | G14: 1. Try to change any amount, line or billing detail on it. | H14: - | I14: Nothing can be edited. The only correction path is cancel + credit note (biên bản) + re-issue — this is a Vietnamese legal requirement.
A15: AD-06-12 | B15: Cancel invoice | C15: Cancelling creates a credit note and links both invoices | D15: Positive | E15: High | F15: You have an Issued invoice with wrong details. | G15: 1. Sign in as Kế toán. 2. Cancel the invoice with a reason. 3. Issue a corrected replacement invoice. 4. Open both records. | H15: Reason: wrong billing address | I15: The cancelled invoice stays on record with status Cancelled. A credit note is produced. The two invoices link to each other in both directions. Nothing is deleted.
... A21: AD-06-18 | B21: Payment | C21: Recording a payment and confirming it against the bank are two different actions | D21: Edge | E21: High | F21: You have an invoiced PO with an unpaid balance. You can sign in as Sales and as Kế toán. | G21: 1. As Sales, record a payment (a receipt arrived). 2. Check what changed on the PO and the deal. 3. As Kế toán, confirm the payment against the bank statement. 4. Check what changed. | H21: - | I21: Sales CAN record a payment; Kế toán alone can confirm it against the bank. Neither one changes the PO status or the deal stage — the money side no longer gates anything upstream. The receivable is closed by the confirmation.

Sheet AD-07 Products on company
A1: AD-07 · Provisioning — products and quota landing on Company detail
A2: Fill in only the yellow columns: Actual Result, Status, Tested By, Test Date, Notes / Bug ID. Status must be one of: Pass, Fail, Blocked, Not Run. If a step does not behave as written in 'Expected Result', mark Fail and write exactly what happened.
A3: Test Case ID | B3: Feature / Screen | C3: Test Case Title | D3: Type | E3: Priority | F3: Pre-condition | G3: Test Steps (do these in order) | H3: Test Data | I3: Expected Result (what you should see) | J3: Actual Result | K3: Status | L3: Tested By | M3: Test Date | N3: Notes / Bug ID
A4: AD-07-01 | B4: Before invoicing | C4: A company with only a PO has nothing on Products & billing | D4: Negative | E4: High | F4: You issued a PO for a brand-new company but have NOT invoiced it. | G4: 1. Open the company detail → Products & billing. 2. Look at Purchased and at Quota in use. | H4: - | I4: Both are empty. No product, no slot, no CV credit. The PO grants nothing, no matter how long it has been Active.
A5: AD-07-02 | B5: On invoice | C5: Issuing the invoice puts the purchased products on the company record | D5: Positive | E5: High | F5: You have an Active PO with 10 Basic job slots and a COMBO 50 CV pack. | G5: 1. Note that Products & billing is empty. 2. Issue the VAT invoice. 3. Refresh the company detail → Products & billing. | H5: 10 job slots + 50 CV unlocks | I5: The product lines appear under Purchased, with the quantity that was invoiced. They appear IMMEDIATELY — there is no queue and no second 'activate' click.
A6: AD-07-03 | B6: On invoice | C6: Job slots and CV unlocks appear as usable quota | D6: Positive | E6: High | F6: You just issued the invoice from AD-07-02. | G6: 1. Open Quota in use on the company detail. | H6: - | I6: 10 job-posting slots at the Basic tier are shown as available balance. 50 CV unlocks are shown, with their 30- or 90-day usage window.
A7: AD-07-04 | B7: On invoice | C7: Gift lines become real quota, exactly like paid ones | D7: Positive | E7: High | F7: The PO contains 5 paid slots and 2 gift '(Tặng)' slots. | G7: 1. Issue the invoice. 2. Look at the quota total on the company. | H7: 5 paid + 2 gift | I7: The company has 7 usable slots. A gift is quota, not a discount — a 0 ₫ line provisions the same as a paid one.
A8: AD-07-05 | B8: First purchase | C8: The first invoice creates the account, the first login and the company page | D8: Positive | E8: High | F8: The company has never bought anything before and has no login. | G8: 1. Issue their first VAT invoice, on a PO containing a Job Posting product. 2. Look for a company account and its users. 3. Look for the public company page. 4. Open the contact's mailbox. | H8: - | I8: The account is created. Exactly ONE first login is created, with the HR Manager role. The public company page is created because they bought Job Posting. An activation email reaches the contact.
A9: AD-07-06 | B9: First purchase | C9: The first company user can activate and sign in | D9: Positive | E9: High | F9: The activation email from AD-07-05 has arrived. | G9: 1. Click the activation link. 2. Set a password. 3. Sign in to the Company site. | H9: - | I9: The user activates, signs in, and lands on the company dashboard with their own company's data only.
A10: AD-07-07 | B10: On invoice | C10: The company can post a job straight after invoicing | D10: Positive | E10: High | F10: The first company user is signed in and quota has been provisioned. | G10: 1. Go to Jobs → Create job. 2. Choose the product they bought. 3. Publish the job. | H10: - | I10: The job publishes with no extra step and no waiting. The employer never had to ask anyone to switch anything on.
A11: AD-07-08 | B11: On invoice | C11: The company can unlock a CV straight after invoicing | D11: Positive | E11: High | F11: The company bought a CV credit pack and it has been invoiced. | G11: 1. Sign in as the company user. 2. Open CV search / Resume list. 3. Unlock one candidate's CV. 4. Check the remaining credits. | H11: - | I11: CV search is available. Unlocking works and the remaining credits drop by exactly 1.
A12: AD-07-09 | B12: Quota | C12: Publishing a job takes exactly one slot from the right tier | D12: Positive | E12: High | F12: The company has 10 Basic slots and 2 Top Job slots. | G12: 1. Note both balances. 2. Publish a job on the Basic product. 3. Check both balances. 4. Save another job as a DRAFT and check the balances again. | H12: - | I12: Basic goes from 10 to 9. Top Job is untouched. Saving a DRAFT consumes nothing — only publishing (Open or Schedule) does.
A13: AD-07-10 | B13: Quota | C13: When the quota reaches zero the action is blocked with a way to buy more | D13: Negative | E13: High | F13: The company has exactly 1 posting slot left. | G13: 1. Publish a job — the balance should reach 0. 2. Try to publish another one. 3. Read the message. | H13: - | I13: The second publish is blocked. The message offers a path to buy more (a deep link to purchase a package), not a dead end.
A14: AD-07-11 | B14: Quota | C14: The company page exists only while Job Posting is entitled | D14: Edge | E14: Medium | F14: A company bought Job Posting and has a public company page. | G14: 1. Open the public company page from the jobseeker site. 2. Ask a developer / accountant to cancel the invoice that granted Job Posting. 3. Open the public company page again. | H14: - | I14: The page exists while the entitlement does. When the entitlement is withdrawn, the page is no longer public. Write down exactly what a jobseeker sees at that URL afterwards.
A15: AD-07-12 | B15: Entitlement | C15: Each entitlement shows which invoice it came from | D15: Positive | E15: Medium | F15: The company has provisioned products. | G15: 1. Open the company detail → Products & billing. 2. Look at a purchased line. | H15: - | I15: Each line links back to the PO / invoice it came from, so you can always answer 'where did this quota come from?'
... A17: AD-07-14 | B17: Entitlement | C17: Quota is never picked by hand | D17: Negative | E17: High | F17: You are an Admin user on a company record. | G17: 1. Look for any control that lets you add a product or quota manually. | H17: - | I17: There is no manual product picker. Quota only ever comes from an issued invoice (or from an explicit, audited manual grant — if you find one, note who is allowed to use it).

Sheet AD-08 Create job
A1: AD-08 · Create and manage a job (Admin and Company site)
A2: Fill in only the yellow columns: Actual Result, Status, Tested By, Test Date, Notes / Bug ID. Status must be one of: Pass, Fail, Blocked, Not Run. If a step does not behave as written in 'Expected Result', mark Fail and write exactly what happened.
A3: Test Case ID | B3: Feature / Screen | C3: Test Case Title | D3: Type | E3: Priority | F3: Pre-condition | G3: Test Steps (do these in order) | H3: Test Data | I3: Expected Result (what you should see) | J3: Actual Result | K3: Status | L3: Tested By | M3: Test Date | N3: Notes / Bug ID
A4: AD-08-01 | B4: Create job (Admin) | C4: HQ can post a job for any company | D4: Positive | E4: High | F4: You are signed in to Admin. Several companies exist. | G4: 1. Go to Recruitment → Jobs → '+ New job'. 2. Search for a company in the company picker and choose it. 3. Fill the job and publish it. | H4: - | I4: Any company can be chosen from the picker. The job is created against that company and goes live with NO approval step.
A5: AD-08-02 | B5: Create job (Admin) | C5: The free tier needs no PO and has no limit | D5: Positive | E5: High | F5: A company has NO active PO at all. | G5: 1. Create a job for it in Admin. 2. Leave the PO field empty. 3. Look at the product list. 4. Choose the free tier and publish. 5. Repeat 3 more times for the same company. | H5: - | I5: With no PO chosen, only the 'Always available' free tier appears. It publishes with no PO and no quota check. All four free jobs publish — there is no limit on the free tier.
A6: AD-08-03 | B6: Create job (Admin) | C6: Choosing a PO first narrows the product list to that PO's lines | D6: Positive | E6: High | F6: A company has TWO active POs with different products on each. | G6: 1. Create a job for that company. 2. Choose PO number 1 and open the product list. 3. Change to PO number 2 and open the product list again. | H6: Two POs with different products | I6: The product list shows only the lines of the PO you selected. Changing the PO changes the products offered. The filter is driven by what was actually bought, not by matching product names.
A7: AD-08-04 | B7: Create job (Company) | C7: A company user can NEVER post a free job | D7: Negative | E7: High | F7: You are signed in to the Company site as an HR Manager, on a company that has bought products. | G7: 1. Start creating a job. 2. Open the product / package list and read every option. | H7: - | I7: The free tier is not offered at all on the Company site. Only products the company actually bought (active PO lines) appear.
A8: AD-08-05 | B8: Create job (Company) | C8: The company is fixed to the user's own company | D8: Negative | E8: High | F8: You are signed in to the Company site. | G8: 1. Start creating a job. 2. Look at the company field. 3. Try to change it. | H8: - | I8: The company is set to your own and cannot be changed. There is no company picker on this surface.
A9: AD-08-06 | B9: Create job | C9: Work type and contract type are TWO separate fields | D9: Positive | E9: High | F9: You are on the job form (either surface). | G9: 1. Find the work type field and read its values. 2. Find the contract type field and read its values. 3. Set work type = remote AND contract type = fulltime. 4. Save. | H9: Remote + Fulltime | I9: There are TWO fields. Work type has 4 values: in office, remote, hybrid, oversea (labelled 'Hình thức làm việc'). Contract type has 7: fulltime, part-time, contract, internship, probation, freelance, seasonal. A full-time remote job can be described without losing either half. Neither list has an 'Other' value.
A10: AD-08-07 | B10: Create job | C10: Vietnamese content is required; English is optional and falls back | D10: Negative | E10: High | F10: You are on the job form. | G10: 1. Fill the title, role & responsibility and skills & qualifications in the EN tab only. Try to publish. 2. Fill the VI tab and leave EN empty. Publish. 3. Open the job on the jobseeker site in English. | H10: - | I10: Publishing is refused while Vietnamese is missing. It publishes with Vietnamese only. On the jobseeker side, the Vietnamese text is shown where the English translation is missing.
