Workbook

Sheet HƯỚNG DẪN
A1: SARAMIN VN — HQ ADMIN · DANH MỤC MÀN HÌNH (Screen inventory)
A3: File này liệt kê TOÀN BỘ màn hình của trang HQ Admin, theo đúng ba cấp: Nhóm menu (tab lớn) → Trang → Tab / Section bên trong trang.
A4: Mỗi dòng là một đơn vị nhỏ nhất — một tab, một section, một form, một modal hoặc một hành động. Đây là đơn vị để khách hàng xác nhận và để mình phân công người kiểm tra.
A5: Tên nhóm menu, tên trang và tên tab được lấy ĐÚNG như đang hiển thị trên prototype, để đọc file và mở màn hình không bị lệch tên.
A6: Cách dùng: đi từ trên xuống, mở mockup theo cột “Link mockup”, rồi điền 3 cột vàng — Người check, KH xác nhận, Ghi chú.
A8: CÁC CỘT TRONG SHEET “DANH MỤC MÀN HÌNH”
A9: Nhóm menu / Trang / Tab | B9: Ba cấp của cây menu. Giá trị được lặp lại trên từng dòng để lọc (Filter) chạy đúng — không phải lỗi trình bày.
A10: Loại / Type | B10: Dòng này là gì: Tab · Tab trạng thái · Bộ lọc · Bảng danh sách · Trang chi tiết · Form tạo mới · Bước trong form · Modal · Khối/Section · Hành động.
A11: Mockup ID | B11: Mã màn hình trong prototype. Dùng để tìm nhanh và để dev/BA nói cùng một tên.
A12: Link mockup | B12: Đường dẫn mở đúng màn hình đó trên trang spec. Ghép sau tên miền của trang spec là mở được.
A13: Spec (module → feature) | B13: Yêu cầu chi tiết của màn hình nằm ở module nào trong tài liệu spec.
A14: BA | B14: BA đang phụ trách module đó.
A15: Người check (vàng) | B15: Mình điền: ai sẽ rà màn hình này.
A16: KH xác nhận (vàng) | B16: Khách chọn: OK · Cần sửa · Chưa xem · Không cần (bỏ khỏi phạm vi).
A17: Ghi chú của KH (vàng) | B17: Khách viết yêu cầu sửa cụ thể. Một dòng = một màn hình, nên ghi chú không bị lẫn.
A19: QUY ƯỚC ĐỌC
A20: Tab trạng thái | B20: Các tab lọc phía trên bảng (All · Draft · Open…). Tách thành từng dòng vì mỗi tab là một danh sách khách phải xác nhận riêng.
A21: Bước trong form | B21: Một bước / một khối của form nhiều bước (ví dụ báo giá có 5 bước). Xác nhận theo từng bước sẽ gọn hơn xác nhận cả form.
A22: Hành động | B22: Nút tạo ra thay đổi thật (Issue PO, Xuất hoá đơn, Block user…). Đây là nhóm cần khách xác nhận kỹ nhất vì liên quan quyền và tiền.
A23: Màu nền theo nhóm menu | B23: Mỗi nhóm menu một màu nhạt, để cuộn nhanh vẫn biết đang ở đâu.
A25: BA CẤP CỦA HQ ADMIN
A26: 7 nhóm menu | B26: Analytics · Recruitment · Service · User · CRM · Products · System.
A27: Trang | B27: Mục con trong nhóm menu — chính là các dòng trong sidebar bên trái.
A28: Tab / Section | B28: Bên trong một trang. Ví dụ trang Company detail có 8 tab: Overview · Contacts · Users · Products & billing · Company page · Jobs · Applications · Resumes.

Sheet TỔNG HỢP
A1: Tổng hợp theo trang — tiến độ xác nhận của khách hàng
A2: Các con số tự tính từ sheet DANH MỤC MÀN HÌNH. Không cần gõ gì ở đây.
A4: Nhóm menu | B4: Trang | C4: Mockup ID | D4: Số dòng | E4: OK | F4: Cần sửa | G4: Chưa xem | H4: Không cần
A5: Analytics | B5: Dashboard | C5: admin-analytics-dashboard | D5: 2 | E5: =COUNTIF('DANH MỤC MÀN HÌNH'!$M$4:$M$5,"OK") | F5: =COUNTIF('DANH MỤC MÀN HÌNH'!$M$4:$M$5,"Cần sửa") | G5: =COUNTIF('DANH MỤC MÀN HÌNH'!$M$4:$M$5,"Chưa xem") | H5: =COUNTIF('DANH MỤC MÀN HÌNH'!$M$4:$M$5,"Không cần")
A6: Analytics | B6: Sales report | C6: admin-sales-report | D6: 2 | E6: =COUNTIF('DANH MỤC MÀN HÌNH'!$M$6:$M$7,"OK") | F6: =COUNTIF('DANH MỤC MÀN HÌNH'!$M$6:$M$7,"Cần sửa") | G6: =COUNTIF('DANH MỤC MÀN HÌNH'!$M$6:$M$7,"Chưa xem") | H6: =COUNTIF('DANH MỤC MÀN HÌNH'!$M$6:$M$7,"Không cần")
A7: Analytics | B7: Recruit report | C7: admin-recruit-report | D7: 1 | E7: =COUNTIF('DANH MỤC MÀN HÌNH'!$M$8:$M$8,"OK") | F7: =COUNTIF('DANH MỤC MÀN HÌNH'!$M$8:$M$8,"Cần sửa") | G7: =COUNTIF('DANH MỤC MÀN HÌNH'!$M$8:$M$8,"Chưa xem") | H7: =COUNTIF('DANH MỤC MÀN HÌNH'!$M$8:$M$8,"Không cần")
A8: Analytics | B8: Revenue report | C8: admin-revenue-report | D8: 2 | E8: =COUNTIF('DANH MỤC MÀN HÌNH'!$M$9:$M$10,"OK") | F8: =COUNTIF('DANH MỤC MÀN HÌNH'!$M$9:$M$10,"Cần sửa") | G8: =COUNTIF('DANH MỤC MÀN HÌNH'!$M$9:$M$10,"Chưa xem") | H8: =COUNTIF('DANH MỤC MÀN HÌNH'!$M$9:$M$10,"Không cần")
A9: Recruitment | B9: Jobs | C9: admin-job-list | D9: 20 | E9: =COUNTIF('DANH MỤC MÀN HÌNH'!$M$11:$M$30,"OK") | F9: =COUNTIF('DANH MỤC MÀN HÌNH'!$M$11:$M$30,"Cần sửa") | G9: =COUNTIF('DANH MỤC MÀN HÌNH'!$M$11:$M$30,"Chưa xem") | H9: =COUNTIF('DANH MỤC MÀN HÌNH'!$M$11:$M$30,"Không cần")
A10: Recruitment | B10: Applicants | C10: admin-job-applicants | D10: 7 | E10: =COUNTIF('DANH MỤC MÀN HÌNH'!$M$31:$M$37,"OK") | F10: =COUNTIF('DANH MỤC MÀN HÌNH'!$M$31:$M$37,"Cần sửa") | G10: =COUNTIF('DANH MỤC MÀN HÌNH'!$M$31:$M$37,"Chưa xem") | H10: =COUNTIF('DANH MỤC MÀN HÌNH'!$M$31:$M$37,"Không cần")
A11: Recruitment | B11: Resumes | C11: admin-resumes | D11: 12 | E11: =COUNTIF('DANH MỤC MÀN HÌNH'!$M$38:$M$49,"OK") | F11: =COUNTIF('DANH MỤC MÀN HÌNH'!$M$38:$M$49,"Cần sửa") | G11: =COUNTIF('DANH MỤC MÀN HÌNH'!$M$38:$M$49,"Chưa xem") | H11: =COUNTIF('DANH MỤC MÀN HÌNH'!$M$38:$M$49,"Không cần")
A12: Service | B12: Displays | C12: admin-banners | D12: 5 | E12: =COUNTIF('DANH MỤC MÀN HÌNH'!$M$50:$M$54,"OK") | F12: =COUNTIF('DANH MỤC MÀN HÌNH'!$M$50:$M$54,"Cần sửa") | G12: =COUNTIF('DANH MỤC MÀN HÌNH'!$M$50:$M$54,"Chưa xem") | H12: =COUNTIF('DANH MỤC MÀN HÌNH'!$M$50:$M$54,"Không cần")
A13: Service | B13: Manual services | C13: admin-manual-services | D13: 2 | E13: =COUNTIF('DANH MỤC MÀN HÌNH'!$M$55:$M$56,"OK") | F13: =COUNTIF('DANH MỤC MÀN HÌNH'!$M$55:$M$56,"Cần sửa") | G13: =COUNTIF('DANH MỤC MÀN HÌNH'!$M$55:$M$56,"Chưa xem") | H13: =COUNTIF('DANH MỤC MÀN HÌNH'!$M$55:$M$56,"Không cần")
A14: User | B14: Jobseeker users | C14: admin-jobseekers | D14: 11 | E14: =COUNTIF('DANH MỤC MÀN HÌNH'!$M$57:$M$67,"OK") | F14: =COUNTIF('DANH MỤC MÀN HÌNH'!$M$57:$M$67,"Cần sửa") | G14: =COUNTIF('DANH MỤC MÀN HÌNH'!$M$57:$M$67,"Chưa xem") | H14: =COUNTIF('DANH MỤC MÀN HÌNH'!$M$57:$M$67,"Không cần")
A15: User | B15: Company users | C15: admin-company-users | D15: 6 | E15: =COUNTIF('DANH MỤC MÀN HÌNH'!$M$68:$M$73,"OK") | F15: =COUNTIF('DANH MỤC MÀN HÌNH'!$M$68:$M$73,"Cần sửa") | G15: =COUNTIF('DANH MỤC MÀN HÌNH'!$M$68:$M$73,"Chưa xem") | H15: =COUNTIF('DANH MỤC MÀN HÌNH'!$M$68:$M$73,"Không cần")
A16: CRM | B16: Companies | C16: admin-company-list | D16: 22 | E16: =COUNTIF('DANH MỤC MÀN HÌNH'!$M$74:$M$95,"OK") | F16: =COUNTIF('DANH MỤC MÀN HÌNH'!$M$74:$M$95,"Cần sửa") | G16: =COUNTIF('DANH MỤC MÀN HÌNH'!$M$74:$M$95,"Chưa xem") | H16: =COUNTIF('DANH MỤC MÀN HÌNH'!$M$74:$M$95,"Không cần")
A17: CRM | B17: Pipeline | C17: admin-company-pipeline | D17: 13 | E17: =COUNTIF('DANH MỤC MÀN HÌNH'!$M$96:$M$108,"OK") | F17: =COUNTIF('DANH MỤC MÀN HÌNH'!$M$96:$M$108,"Cần sửa") | G17: =COUNTIF('DANH MỤC MÀN HÌNH'!$M$96:$M$108,"Chưa xem") | H17: =COUNTIF('DANH MỤC MÀN HÌNH'!$M$96:$M$108,"Không cần")
A18: CRM | B18: Quotations | C18: admin-quotes | D18: 10 | E18: =COUNTIF('DANH MỤC MÀN HÌNH'!$M$109:$M$118,"OK") | F18: =COUNTIF('DANH MỤC MÀN HÌNH'!$M$109:$M$118,"Cần sửa") | G18: =COUNTIF('DANH MỤC MÀN HÌNH'!$M$109:$M$118,"Chưa xem") | H18: =COUNTIF('DANH MỤC MÀN HÌNH'!$M$109:$M$118,"Không cần")
A19: CRM | B19: Purchase order | C19: admin-purchase-orders | D19: 8 | E19: =COUNTIF('DANH MỤC MÀN HÌNH'!$M$119:$M$126,"OK") | F19: =COUNTIF('DANH MỤC MÀN HÌNH'!$M$119:$M$126,"Cần sửa") | G19: =COUNTIF('DANH MỤC MÀN HÌNH'!$M$119:$M$126,"Chưa xem") | H19: =COUNTIF('DANH MỤC MÀN HÌNH'!$M$119:$M$126,"Không cần")
A20: CRM | B20: Invoice | C20: admin-invoices | D20: 8 | E20: =COUNTIF('DANH MỤC MÀN HÌNH'!$M$127:$M$134,"OK") | F20: =COUNTIF('DANH MỤC MÀN HÌNH'!$M$127:$M$134,"Cần sửa") | G20: =COUNTIF('DANH MỤC MÀN HÌNH'!$M$127:$M$134,"Chưa xem") | H20: =COUNTIF('DANH MỤC MÀN HÌNH'!$M$127:$M$134,"Không cần")
A21: CRM | B21: Sign-ups | C21: admin-signups | D21: 8 | E21: =COUNTIF('DANH MỤC MÀN HÌNH'!$M$135:$M$142,"OK") | F21: =COUNTIF('DANH MỤC MÀN HÌNH'!$M$135:$M$142,"Cần sửa") | G21: =COUNTIF('DANH MỤC MÀN HÌNH'!$M$135:$M$142,"Chưa xem") | H21: =COUNTIF('DANH MỤC MÀN HÌNH'!$M$135:$M$142,"Không cần")
A22: CRM | B22: Account usage | C22: admin-account-usage | D22: 2 | E22: =COUNTIF('DANH MỤC MÀN HÌNH'!$M$143:$M$144,"OK") | F22: =COUNTIF('DANH MỤC MÀN HÌNH'!$M$143:$M$144,"Cần sửa") | G22: =COUNTIF('DANH MỤC MÀN HÌNH'!$M$143:$M$144,"Chưa xem") | H22: =COUNTIF('DANH MỤC MÀN HÌNH'!$M$143:$M$144,"Không cần")
A23: Products | B23: Products | C23: admin-catalog | D23: 9 | E23: =COUNTIF('DANH MỤC MÀN HÌNH'!$M$145:$M$153,"OK") | F23: =COUNTIF('DANH MỤC MÀN HÌNH'!$M$145:$M$153,"Cần sửa") | G23: =COUNTIF('DANH MỤC MÀN HÌNH'!$M$145:$M$153,"Chưa xem") | H23: =COUNTIF('DANH MỤC MÀN HÌNH'!$M$145:$M$153,"Không cần")
A24: Products | B24: Packages | C24: admin-bundles | D24: 5 | E24: =COUNTIF('DANH MỤC MÀN HÌNH'!$M$154:$M$158,"OK") | F24: =COUNTIF('DANH MỤC MÀN HÌNH'!$M$154:$M$158,"Cần sửa") | G24: =COUNTIF('DANH MỤC MÀN HÌNH'!$M$154:$M$158,"Chưa xem") | H24: =COUNTIF('DANH MỤC MÀN HÌNH'!$M$154:$M$158,"Không cần")
A25: Products | B25: Placements | C25: admin-placements | D25: 2 | E25: =COUNTIF('DANH MỤC MÀN HÌNH'!$M$159:$M$160,"OK") | F25: =COUNTIF('DANH MỤC MÀN HÌNH'!$M$159:$M$160,"Cần sửa") | G25: =COUNTIF('DANH MỤC MÀN HÌNH'!$M$159:$M$160,"Chưa xem") | H25: =COUNTIF('DANH MỤC MÀN HÌNH'!$M$159:$M$160,"Không cần")
A26: Products | B26: Discount programmes | C26: admin-promotions | D26: 4 | E26: =COUNTIF('DANH MỤC MÀN HÌNH'!$M$161:$M$164,"OK") | F26: =COUNTIF('DANH MỤC MÀN HÌNH'!$M$161:$M$164,"Cần sửa") | G26: =COUNTIF('DANH MỤC MÀN HÌNH'!$M$161:$M$164,"Chưa xem") | H26: =COUNTIF('DANH MỤC MÀN HÌNH'!$M$161:$M$164,"Không cần")
A27: System | B27: Staff directory | C27: admin-staff | D27: 2 | E27: =COUNTIF('DANH MỤC MÀN HÌNH'!$M$165:$M$166,"OK") | F27: =COUNTIF('DANH MỤC MÀN HÌNH'!$M$165:$M$166,"Cần sửa") | G27: =COUNTIF('DANH MỤC MÀN HÌNH'!$M$165:$M$166,"Chưa xem") | H27: =COUNTIF('DANH MỤC MÀN HÌNH'!$M$165:$M$166,"Không cần")
A28: System | B28: Users | C28: admin-users | D28: 5 | E28: =COUNTIF('DANH MỤC MÀN HÌNH'!$M$167:$M$171,"OK") | F28: =COUNTIF('DANH MỤC MÀN HÌNH'!$M$167:$M$171,"Cần sửa") | G28: =COUNTIF('DANH MỤC MÀN HÌNH'!$M$167:$M$171,"Chưa xem") | H28: =COUNTIF('DANH MỤC MÀN HÌNH'!$M$167:$M$171,"Không cần")
A29: System | B29: Roles & permissions | C29: admin-roles | D29: 2 | E29: =COUNTIF('DANH MỤC MÀN HÌNH'!$M$172:$M$173,"OK") | F29: =COUNTIF('DANH MỤC MÀN HÌNH'!$M$172:$M$173,"Cần sửa") | G29: =COUNTIF('DANH MỤC MÀN HÌNH'!$M$172:$M$173,"Chưa xem") | H29: =COUNTIF('DANH MỤC MÀN HÌNH'!$M$172:$M$173,"Không cần")
A30: System | B30: Company information | C30: admin-issuer | D30: 5 | E30: =COUNTIF('DANH MỤC MÀN HÌNH'!$M$174:$M$178,"OK") | F30: =COUNTIF('DANH MỤC MÀN HÌNH'!$M$174:$M$178,"Cần sửa") | G30: =COUNTIF('DANH MỤC MÀN HÌNH'!$M$174:$M$178,"Chưa xem") | H30: =COUNTIF('DANH MỤC MÀN HÌNH'!$M$174:$M$178,"Không cần")
A31: System | B31: Membership tiers | C31: admin-membership | D31: 2 | E31: =COUNTIF('DANH MỤC MÀN HÌNH'!$M$179:$M$180,"OK") | F31: =COUNTIF('DANH MỤC MÀN HÌNH'!$M$179:$M$180,"Cần sửa") | G31: =COUNTIF('DANH MỤC MÀN HÌNH'!$M$179:$M$180,"Chưa xem") | H31: =COUNTIF('DANH MỤC MÀN HÌNH'!$M$179:$M$180,"Không cần")
A32: System | B32: Pages | C32: admin-pages | D32: 4 | E32: =COUNTIF('DANH MỤC MÀN HÌNH'!$M$181:$M$184,"OK") | F32: =COUNTIF('DANH MỤC MÀN HÌNH'!$M$181:$M$184,"Cần sửa") | G32: =COUNTIF('DANH MỤC MÀN HÌNH'!$M$181:$M$184,"Chưa xem") | H32: =COUNTIF('DANH MỤC MÀN HÌNH'!$M$181:$M$184,"Không cần")
A33: System | B33: Master data | C33: admin-master-data | D33: 14 | E33: =COUNTIF('DANH MỤC MÀN HÌNH'!$M$185:$M$198,"OK") | F33: =COUNTIF('DANH MỤC MÀN HÌNH'!$M$185:$M$198,"Cần sửa") | G33: =COUNTIF('DANH MỤC MÀN HÌNH'!$M$185:$M$198,"Chưa xem") | H33: =COUNTIF('DANH MỤC MÀN HÌNH'!$M$185:$M$198,"Không cần")
A34: System | B34: Audit log | C34: admin-audit-log | D34: 1 | E34: =COUNTIF('DANH MỤC MÀN HÌNH'!$M$199:$M$199,"OK") | F34: =COUNTIF('DANH MỤC MÀN HÌNH'!$M$199:$M$199,"Cần sửa") | G34: =COUNTIF('DANH MỤC MÀN HÌNH'!$M$199:$M$199,"Chưa xem") | H34: =COUNTIF('DANH MỤC MÀN HÌNH'!$M$199:$M$199,"Không cần")
A35: System | B35: Environment | C35: admin-environment | D35: 1 | E35: =COUNTIF('DANH MỤC MÀN HÌNH'!$M$200:$M$200,"OK") | F35: =COUNTIF('DANH MỤC MÀN HÌNH'!$M$200:$M$200,"Cần sửa") | G35: =COUNTIF('DANH MỤC MÀN HÌNH'!$M$200:$M$200,"Chưa xem") | H35: =COUNTIF('DANH MỤC MÀN HÌNH'!$M$200:$M$200,"Không cần")
A36: System | B36: Departments | C36: admin-departments | D36: 2 | E36: =COUNTIF('DANH MỤC MÀN HÌNH'!$M$201:$M$202,"OK") | F36: =COUNTIF('DANH MỤC MÀN HÌNH'!$M$201:$M$202,"Cần sửa") | G36: =COUNTIF('DANH MỤC MÀN HÌNH'!$M$201:$M$202,"Chưa xem") | H36: =COUNTIF('DANH MỤC MÀN HÌNH'!$M$201:$M$202,"Không cần")
A37: TỔNG | D37: =SUM(D5:D36) | E37: =SUM(E5:E36) | F37: =SUM(F5:F36) | G37: =SUM(G5:G36) | H37: =SUM(H5:H36)
A39: Theo nhóm menu
A40: Nhóm menu | B40: Số trang | C40: Số dòng
A41: Analytics | B41: 4 | C41: 7
A42: Recruitment | B42: 3 | C42: 39
...

Sheet DANH MỤC MÀN HÌNH
A1: HQ Admin — danh mục màn hình để xác nhận & phân công
A2: Mỗi dòng là một đơn vị nhỏ nhất (tab / section / form / hành động). Khách hàng điền cột “KH xác nhận” và “Ghi chú”; nội bộ điền cột “Người check”. Ba cột này được tô vàng.
A3: STT | B3: ID | C3: Nhóm menu Nav group | D3: Trang Page | E3: Tab / Section (đơn vị nhỏ nhất) | F3: Loại Type | G3: Nội dung màn hình này là gì What this screen is | H3: Mockup ID | I3: Link mockup | J3: Spec (module → feature) | K3: BA | L3: Người check Assigned to | M3: KH xác nhận Client confirm | N3: Ghi chú của KH / Comment
A4: 1 | B4: AD-ANA-DAS-01 | C4: Analytics | D4: Dashboard | E4: Thẻ chỉ số | F4: Khối / Section | G4: Revenue (MTD) · Active jobs · New applicants · Paying companies — kèm % so với tháng trước. | H4: admin-analytics-dashboard | I4: /wireframe/admin?screen=admin-analytics-dashboard | J4: — | K4: —
A5: 2 | B5: AD-ANA-DAS-02 | C5: Analytics | D5: Dashboard | E5: Biểu đồ doanh thu 6 tháng | F5: Khối / Section | G5: Cột doanh thu theo tháng (tỷ ₫). | H5: admin-analytics-dashboard | I5: /wireframe/admin?screen=admin-analytics-dashboard | J5: — | K5: —
A6: 3 | B6: AD-ANA-SAL-01 | C6: Analytics | D6: Sales report | E6: Thẻ chỉ số | F6: Khối / Section | G6: Bookings (MTD) · Avg deal size · Win rate · Open pipeline. | H6: admin-sales-report | I6: /wireframe/admin?screen=admin-sales-report | J6: — | K6: —
A7: 4 | B7: AD-ANA-SAL-02 | C7: Analytics | D7: Sales report | E7: Bảng doanh thu theo sản phẩm | F7: Bảng danh sách | G7: Product · Units sold · Revenue · Share. | H7: admin-sales-report | I7: /wireframe/admin?screen=admin-sales-report | J7: — | K7: —
A8: 5 | B8: AD-ANA-REC-01 | C8: Analytics | D8: Recruit report | E8: Phễu tuyển dụng 30 ngày | F8: Khối / Section | G8: Views → Applies → Screened → Interview → Hired, kèm apply rate / hire rate. | H8: admin-recruit-report | I8: /wireframe/admin?screen=admin-recruit-report | J8: — | K8: —
A9: 6 | B9: AD-ANA-REV-01 | C9: Analytics | D9: Revenue report | E9: Thẻ chỉ số | F9: Khối / Section | G9: Revenue (YTD) · Recognized · Deferred · Refunds. | H9: admin-revenue-report | I9: /wireframe/admin?screen=admin-revenue-report | J9: — | K9: —
A10: 7 | B10: AD-ANA-REV-02 | C10: Analytics | D10: Revenue report | E10: Bảng doanh thu theo tháng | F10: Bảng danh sách | G10: Month · Bookings · Recognized · Refunds. | H10: admin-revenue-report | I10: /wireframe/admin?screen=admin-revenue-report | J10: — | K10: —
A11: 8 | B11: AD-REC-JOB-01 | C11: Recruitment | D11: Jobs | E11: All | F11: Tab trạng thái | G11: Toàn bộ tin đăng của mọi công ty, kèm số đếm trên tab. | H11: admin-job-list | I11: /wireframe/admin?screen=admin-job-list | J11: Job management → Job list (Admin) | K11: Luan
A12: 9 | B12: AD-REC-JOB-02 | C12: Recruitment | D12: Jobs | E12: Draft | F12: Tab trạng thái | G12: Tin đã lưu nhưng chưa đăng. Không hiện trên site jobseeker. | H12: admin-job-list | I12: /wireframe/admin?screen=admin-job-list | J12: Job management → Job list (Admin) | K12: Luan
A13: 10 | B13: AD-REC-JOB-03 | C13: Recruitment | D13: Jobs | E13: Schedule | F13: Tab trạng thái | G13: Tin hẹn giờ đăng — tự động chuyển sang Open đúng giờ. | H13: admin-job-list | I13: /wireframe/admin?screen=admin-job-list | J13: Job management → Job list (Admin) | K13: Luan
A14: 11 | B14: AD-REC-JOB-04 | C14: Recruitment | D14: Jobs | E14: Open | F14: Tab trạng thái | G14: Tin đang chạy. Chỉ Open + Exposure On mới hiển thị cho jobseeker. | H14: admin-job-list | I14: /wireframe/admin?screen=admin-job-list | J14: Job management → Job list (Admin) | K14: Luan
A15: 12 | B15: AD-REC-JOB-05 | C15: Recruitment | D15: Jobs | E15: Closed | F15: Tab trạng thái | G15: Tin đã hết hạn hoặc đóng thủ công. Không ứng tuyển được. | H15: admin-job-list | I15: /wireframe/admin?screen=admin-job-list | J15: Job management → Job list (Admin) | K15: Luan
... A202: 199 | B202: AD-SYS-DEP-02 | C202: System | D202: Departments | E202: Department detail | F202: Trang chi tiết | G202: Thành viên và người phụ trách. | H202: admin-departments | I202: /wireframe/admin?screen=admin-departments | J202: Admin & access → Departments | K202: Luong
