Workbook

Sheet READ ME FIRST
A1: SARAMIN VN — TEST CASES · FILE 1 of 2 · JOBSEEKER
A3: This workbook covers everything a jobseeker does: creating an account, signing in, onboarding, building and managing a CV, finding jobs, applying, and closing the account.
A4: File 2 (Admin & Company) covers the other side: product, company, quotation, PO, invoice, and posting the jobs that show up here.
A5: You do not need to know the system to use this workbook. Every test case tells you what to set up, what to click, and what you should see.
A6: If anything in a test case does not match the product you are testing, do not guess — mark it Fail or Blocked and write down exactly what you saw. A test case that is wrong is also useful information.
A8: WHAT IS IN EACH SHEET
A9: SUMMARY | B9: Counts Pass / Fail / Blocked / Not Run automatically from every sheet. You never type in it — it fills itself from the Status column.
A10: JS-01 Sign up email | B10: Creating an account with email + password, and confirming the email address.
A11: JS-02 Social login | B11: Signing up and signing in with Facebook, Google, LinkedIn and GitHub, and the completion step that follows.
A12: JS-03 Sign in | B12: Signing in, forgotten password, lockout, and what happens for suspended / deactivated accounts.
A13: JS-04 Onboarding | B13: The 4-step wizard that runs straight after sign-up, and the matched-jobs page at the end.
A14: JS-05 Create CV | B14: Uploading a CV file, converting it to a Saramin CV, and building one from scratch.
A15: JS-06 Manage CV | B15: My CVs: which CV employers can find, visibility, unlock history, rename, delete, replace.
A16: JS-07 Find jobs | B16: Homepage rails, search with filters and sorting, and the job detail page.
A17: JS-08 Apply to a job | B17: The apply screen, what it pre-fills, and everything that must stop a bad application.
A18: JS-09 My applications | B18: Tracking an application and checking the status matches what the employer set.
A19: JS-10 My page | B19: Profile, avatar, email change, notification settings, and deactivating the account.
A20: BUG LOG | B20: One row per failed test case. Delete the grey example row before you start.
A22: WORDS YOU WILL SEE (plain English)
A23: Jobseeker | B23: The person looking for a job. Also called 'candidate'.
A24: Employer / Company user | B24: The person at a company who posts jobs and reads applications.
A25: Admin / HQ | B25: Saramin's own staff, working in the Admin site.
A26: Pending verification | B26: An account that has signed up but has not clicked the link in the email yet. It can browse, but it cannot apply.
A27: Active | B27: A fully working account. Only an Active account can apply to a job.
A28: Suspended | B28: An account blocked by Saramin staff. It cannot sign in.
A29: Deactivated | B29: An account the person closed themselves. It can come back within a grace window.
A30: Completion step | B30: The extra screen after a social sign-up that asks for the phone number and the Terms — a provider cannot give us those.
A31: Onboarding | B31: The short 4-step wizard that runs right after an account is created.
A32: Searchable CV | B32: The ONE CV that employers can find you by. Your other CVs still work for applying.
A33: Discoverable / Hidden | B33: Whether employers can find you at all in CV search. This is your own consent — nobody else can change it.
A34: Open / Exposure On | B34: A job is only visible to jobseekers when its status is Open AND its exposure switch is On. Both must be true.
... A36: Snapshot | B36: A frozen copy. Your CV is snapshotted when you apply, so later edits do not change what the employer received.
A38: HOW TO RUN A TEST CASE
A39: 1. Read the Pre-condition | B39: This is what must already be true before you start. If you cannot set it up, put Blocked in Status and say why.
A40: 2. Do the Test Steps in order | B40: Do not skip a step and do not do them out of order. Each numbered line is one action.
A41: 3. Use the Test Data given | B41: If a value is not given, use anything sensible, then write what you used in Notes.
A42: 4. Compare with Expected Result | B42: Every sentence in Expected Result must be true. If even one is not true, the test Fails.
A43: 5. Fill the yellow columns | B43: Actual Result = what really happened. Status = Pass / Fail / Blocked / Not Run. Add your name and the date.
A44: 6. Raise a bug for every Fail | B44: Put the bug ID in Notes / Bug ID so the developer can find it. A Fail with no bug is lost work.
A45: Screenshots | B45: Always attach a screenshot for a Fail. For anything about money, quota or status, screenshot before AND after.
...

Sheet SUMMARY
A1: Test execution summary
A2: Type Pass / Fail / Blocked / Not Run in the Status column of each sheet — these numbers update by themselves. '% Executed' means how many cases you have actually run (Pass + Fail + Blocked).
A4: Sheet | B4: Total cases | C4: Pass | D4: Fail | E4: Blocked | F4: Not Run | G4: % Executed
A5: JS-01 Sign up email | B5: 18 | C5: =COUNTIF('JS-01 Sign up email'!K:K,"Pass") | D5: =COUNTIF('JS-01 Sign up email'!K:K,"Fail") | E5: =COUNTIF('JS-01 Sign up email'!K:K,"Blocked") | F5: =COUNTIF('JS-01 Sign up email'!K:K,"Not Run") | G5: =IFERROR((C5+D5+E5)/B5,0)
A6: JS-02 Social login | B6: 17 | C6: =COUNTIF('JS-02 Social login'!K:K,"Pass") | D6: =COUNTIF('JS-02 Social login'!K:K,"Fail") | E6: =COUNTIF('JS-02 Social login'!K:K,"Blocked") | F6: =COUNTIF('JS-02 Social login'!K:K,"Not Run") | G6: =IFERROR((C6+D6+E6)/B6,0)
A7: JS-03 Sign in | B7: 13 | C7: =COUNTIF('JS-03 Sign in'!K:K,"Pass") | D7: =COUNTIF('JS-03 Sign in'!K:K,"Fail") | E7: =COUNTIF('JS-03 Sign in'!K:K,"Blocked") | F7: =COUNTIF('JS-03 Sign in'!K:K,"Not Run") | G7: =IFERROR((C7+D7+E7)/B7,0)
A8: JS-04 Onboarding | B8: 16 | C8: =COUNTIF('JS-04 Onboarding'!K:K,"Pass") | D8: =COUNTIF('JS-04 Onboarding'!K:K,"Fail") | E8: =COUNTIF('JS-04 Onboarding'!K:K,"Blocked") | F8: =COUNTIF('JS-04 Onboarding'!K:K,"Not Run") | G8: =IFERROR((C8+D8+E8)/B8,0)
A9: JS-05 Create CV | B9: 28 | C9: =COUNTIF('JS-05 Create CV'!K:K,"Pass") | D9: =COUNTIF('JS-05 Create CV'!K:K,"Fail") | E9: =COUNTIF('JS-05 Create CV'!K:K,"Blocked") | F9: =COUNTIF('JS-05 Create CV'!K:K,"Not Run") | G9: =IFERROR((C9+D9+E9)/B9,0)
A10: JS-06 Manage CV | B10: 17 | C10: =COUNTIF('JS-06 Manage CV'!K:K,"Pass") | D10: =COUNTIF('JS-06 Manage CV'!K:K,"Fail") | E10: =COUNTIF('JS-06 Manage CV'!K:K,"Blocked") | F10: =COUNTIF('JS-06 Manage CV'!K:K,"Not Run") | G10: =IFERROR((C10+D10+E10)/B10,0)
A11: JS-07 Find jobs | B11: 21 | C11: =COUNTIF('JS-07 Find jobs'!K:K,"Pass") | D11: =COUNTIF('JS-07 Find jobs'!K:K,"Fail") | E11: =COUNTIF('JS-07 Find jobs'!K:K,"Blocked") | F11: =COUNTIF('JS-07 Find jobs'!K:K,"Not Run") | G11: =IFERROR((C11+D11+E11)/B11,0)
A12: JS-08 Apply to a job | B12: 20 | C12: =COUNTIF('JS-08 Apply to a job'!K:K,"Pass") | D12: =COUNTIF('JS-08 Apply to a job'!K:K,"Fail") | E12: =COUNTIF('JS-08 Apply to a job'!K:K,"Blocked") | F12: =COUNTIF('JS-08 Apply to a job'!K:K,"Not Run") | G12: =IFERROR((C12+D12+E12)/B12,0)
A13: JS-09 My applications | B13: 10 | C13: =COUNTIF('JS-09 My applications'!K:K,"Pass") | D13: =COUNTIF('JS-09 My applications'!K:K,"Fail") | E13: =COUNTIF('JS-09 My applications'!K:K,"Blocked") | F13: =COUNTIF('JS-09 My applications'!K:K,"Not Run") | G13: =IFERROR((C13+D13+E13)/B13,0)
A14: JS-10 My page | B14: 18 | C14: =COUNTIF('JS-10 My page'!K:K,"Pass") | D14: =COUNTIF('JS-10 My page'!K:K,"Fail") | E14: =COUNTIF('JS-10 My page'!K:K,"Blocked") | F14: =COUNTIF('JS-10 My page'!K:K,"Not Run") | G14: =IFERROR((C14+D14+E14)/B14,0)
A15: TOTAL | B15: =SUM(B5:B14) | C15: =SUM(C5:C14) | D15: =SUM(D5:D14) | E15: =SUM(E5:E14) | F15: =SUM(F5:F14) | G15: =IFERROR((C15+D15+E15)/B15,0)

Sheet JS-01 Sign up email
A1: JS-01 · Sign up with email, and email verification
A2: Fill in only the yellow columns: Actual Result, Status, Tested By, Test Date, Notes / Bug ID. Status must be one of: Pass, Fail, Blocked, Not Run. If a step does not behave as written in 'Expected Result', mark Fail and write exactly what happened.
A3: Test Case ID | B3: Feature / Screen | C3: Test Case Title | D3: Type | E3: Priority | F3: Pre-condition | G3: Test Steps (do these in order) | H3: Test Data | I3: Expected Result (what you should see) | J3: Actual Result | K3: Status | L3: Tested By | M3: Test Date | N3: Notes / Bug ID
A4: JS-01-01 | B4: Sign up (email) | C4: Sign up page opens and shows every field the spec asks for | D4: Positive | E4: High | F4: You are logged out. You are on the Jobseeker homepage. | G4: 1. Click the 'Sign up' button in the page header. 2. Look at the form that opens. 3. Write down every field you can see. | H4: - | I4: The sign-up form opens. It shows: Full name (ONE box, not First name + Last name), Email, Password, Phone, an optional Personal details group (date of birth, nationality, gender, marital status), and a tick box for Terms & Privacy. It also shows 4 social buttons: Facebook, Google, LinkedIn, GitHub.
A5: JS-01-02 | B5: Sign up (email) | C5: Create an account with correct information | D5: Positive | E5: High | F5: You are logged out. The email you will use has never been registered before. | G5: 1. Open the Sign up page. 2. Type a Full name. 3. Type a brand-new email address you can open. 4. Type a password with at least 8 characters, containing letters and numbers. 5. Type a phone number. 6. Tick the Terms & Privacy box. 7. Click 'Create account'. 8. Open the inbox of that email address. | H5: Full name: Nguyen Van Test Email: a fresh address you control Password: Test1234 Phone: 0901234567 | I5: The account is created. You are NOT stopped on a 'check your inbox' dead-end page — you go straight into the Onboarding wizard. A banner appears telling you to confirm your email, with a 'resend' action. A verification email arrives in the inbox.
A6: JS-01-03 | B6: Sign up (email) | C6: Full name is one single box — never split into first name / last name | D6: Positive | E6: Medium | F6: You are on the Sign up page. | G6: 1. Look at the name area of the form. | H6: - | I6: There is exactly ONE box labelled 'Full name'. There is NO 'First name' box and NO 'Last name' box anywhere on the form.
A7: JS-01-04 | B7: Sign up (email) | C7: Sign up is refused when the email is already registered | D7: Negative | E7: High | F7: An account already exists on the email you will type (use the account from JS-01-02). | G7: 1. Open the Sign up page. 2. Fill in the form using an email address that already has an account. 3. Click 'Create account'. | H7: Email: the same one used in JS-01-02 | I7: A second account is NOT created. A message tells you the email is already registered and offers you 'Sign in' or 'Reset password'. You are not left guessing what to do next.
A8: JS-01-05 | B8: Sign up (email) | C8: The same email in CAPITAL letters is still treated as the same account | D8: Edge | E8: High | F8: An account exists on test.user@mail.com. | G8: 1. Open the Sign up page. 2. Type the same email but in capitals: TEST.USER@MAIL.COM. 3. Fill in the other fields. 4. Click 'Create account'. | H8: Email: TEST.USER@MAIL.COM | I8: The sign-up is refused exactly like JS-01-04. Email is stored in small letters, so capitals do not create a second account. (Ask a developer to confirm in the database that only ONE row exists for that email.)
A9: JS-01-06 | B9: Sign up (email) | C9: Password shorter than 8 characters is refused | D9: Negative | E9: High | F9: You are on the Sign up page. | G9: 1. Fill in the form normally. 2. In Password type: Test1 3. Click 'Create account'. | H9: Password: Test1 | I9: The account is not created. An error under the Password box says the password must be at least 8 characters. The rest of what you typed is still on screen — you do not have to type it all again.
A10: JS-01-07 | B10: Sign up (email) | C10: Password with letters only (no number) is refused | D10: Negative | E10: Medium | F10: You are on the Sign up page. | G10: 1. Fill in the form normally. 2. In Password type: testpassword 3. Click 'Create account'. | H10: Password: testpassword | I10: The account is not created. An error says the password must mix letters and numbers. The live rule checklist next to the box shows which rule is not met yet.
A11: JS-01-08 | B11: Sign up (email) | C11: Password strength meter reacts while you type | D11: Positive | E11: Low | F11: You are on the Sign up page. | G11: 1. Click into the Password box. 2. Type slowly: a, then ab, then abc12345, then Abc12345!x 3. Watch the strength meter after each change. | H11: - | I11: The strength meter changes as the password gets stronger. The password is never silently cut short — every character you type is kept.
A12: JS-01-09 | B12: Sign up (email) | C12: Terms & Privacy must be ticked before the account can be created | D12: Negative | E12: High | F12: You are on the Sign up page. | G12: 1. Fill in every field correctly. 2. Do NOT tick the Terms & Privacy box. 3. Try to click 'Create account'. | H12: - | I12: The account is not created. Either the button cannot be pressed, or a message says you must accept the Terms & Privacy first.
A13: JS-01-10 | B13: Sign up (email) | C13: Badly formed email address is refused | D13: Negative | E13: Medium | F13: You are on the Sign up page. | G13: 1. In Email type: test@@mail 2. Fill the rest of the form. 3. Click 'Create account'. | H13: Email: test@@mail | I13: The account is not created and an error says the email address is not valid.
A14: JS-01-11 | B14: Sign up (email) | C14: Personal details (date of birth, nationality, gender, marital status) can be left empty | D14: Positive | E14: Medium | F14: You are on the Sign up page. | G14: 1. Fill in only Full name, Email, Password, Phone and tick the Terms box. 2. Leave every Personal details field empty. 3. Click 'Create account'. | H14: - | I14: The account is created normally. None of the four personal-detail fields is required.
A15: JS-01-12 | B15: Email verification | C15: Clicking the verification link makes the account Active | D15: Positive | E15: High | F15: You have just signed up (JS-01-02) and the account is 'Pending verification'. | G15: 1. Open the verification email. 2. Click the link in it. 3. Look at the page you land on. | H15: - | I15: The account becomes Active. You are signed in. You are taken back to whatever you were doing before (for example the job you wanted to apply to), not to a random page. The 'confirm your email' banner is gone.
... A21: JS-01-18 | B21: Email verification | C21: Password is never stored or shown in plain text | D21: Positive | E21: High | F21: An account exists. You have a developer with database access sitting with you. | G21: 1. Ask the developer to open the jobseeker record in the database. 2. Look at the password column. 3. Search every email the system sent you for your password. | H21: - | I21: The password is stored only as a scrambled hash (bcrypt or argon2) — you cannot read the real password anywhere. No email ever contains the password.

Sheet JS-02 Social login
A1: JS-02 · Sign up and sign in with Facebook / Google / LinkedIn / GitHub
A2: Fill in only the yellow columns: Actual Result, Status, Tested By, Test Date, Notes / Bug ID. Status must be one of: Pass, Fail, Blocked, Not Run. If a step does not behave as written in 'Expected Result', mark Fail and write exactly what happened.
A3: Test Case ID | B3: Feature / Screen | C3: Test Case Title | D3: Type | E3: Priority | F3: Pre-condition | G3: Test Steps (do these in order) | H3: Test Data | I3: Expected Result (what you should see) | J3: Actual Result | K3: Status | L3: Tested By | M3: Test Date | N3: Notes / Bug ID
A4: JS-02-01 | B4: Social sign up | C4: All four social buttons are on Sign up and on Sign in | D4: Positive | E4: High | F4: You are logged out. | G4: 1. Open the Sign up page and look at the social buttons. 2. Open the Sign in page and look at the social buttons. | H4: - | I4: Both pages show the same four buttons: Facebook, Google, LinkedIn, GitHub.
A5: JS-02-02 | B5: Social sign up | C5: Signing up with Google opens the completion step (not straight into the site) | D5: Positive | E5: High | F5: You are logged out. You have a Google account whose email has NEVER been used on the platform. | G5: 1. Open the Sign up page. 2. Click 'Google'. 3. Log in at Google and allow access. 4. Look at the screen you land on. | H5: A Google account not yet registered | I5: You do NOT land on the homepage. A 'completion step' screen opens asking for: Full name (already filled), Phone (empty), and the Terms tick box. The email is shown but LOCKED, with the provider named next to it (for example a padlock and 'Google').
A6: JS-02-03 | B6: Social sign up | C6: The email from the provider cannot be edited on the completion step | D6: Negative | E6: High | F6: You are on the social completion step (JS-03-02). | G6: 1. Try to click into the email box and change it. | H6: - | I6: The email cannot be changed. It is read-only and the provider name is shown beside it. This is because the email is the identity of the account.
A7: JS-02-04 | B7: Social sign up | C7: Full name comes pre-filled from the provider but can still be edited | D7: Positive | E7: High | F7: You are on the social completion step. | G7: 1. Look at the Full name box. 2. Change it to a different name. 3. Finish the sign-up. 4. Open My page and check the name. | H7: Change the name to: Nguyen Van Corrected | I7: The name box arrives pre-filled with the name Google gave. You can edit it freely. The name you typed is the one saved and shown afterwards.
A8: JS-02-05 | B8: Social sign up | C8: Phone is empty and is required before the account can be finished | D8: Negative | E8: High | F8: You are on the social completion step. | G8: 1. Look at the Phone box — it should be empty. 2. Leave it empty. 3. Tick the Terms box. 4. Click the confirm button. | H8: - | I8: The Phone box arrives EMPTY (no social provider ever gives us a phone number). The account cannot be finished with an empty phone — an error appears asking for it. An 'I live abroad' option is offered for people without a Vietnamese number.
A9: JS-02-06 | B9: Social sign up | C9: Terms tick box is required; optional consents are OFF by default | D9: Negative | E9: High | F9: You are on the social completion step. | G9: 1. Fill in the phone. 2. Look at the optional consent switches (location-based terms, marketing email, marketing SMS/Zalo). 3. Do NOT tick the membership Terms box. 4. Try to confirm. | H9: - | I9: The three optional consents are all OFF when the screen opens. Only the membership Terms box blocks the confirm button. Without it, the account cannot be created.
A10: JS-02-07 | B10: Social sign up | C10: 'Agree to all' shortcut turns on every consent at once | D10: Positive | E10: Low | F10: You are on the social completion step. | G10: 1. Click the 'agree to all' shortcut. 2. Look at every tick box. | H10: - | I10: All the consent boxes, including the optional ones, become ticked.
A11: JS-02-08 | B11: Social sign up | C11: Finishing the completion step makes the account Active with NO verification email | D11: Positive | E11: High | F11: You are on the social completion step with the phone filled and Terms ticked. | G11: 1. Click the confirm button ('Đồng ý điều khoản của chúng tôi'). 2. Watch where you land. 3. Open the email inbox of that Google account. | H11: - | I11: The account becomes Active straight away. You go into the Onboarding wizard. NO verification email is sent — the provider already verified the email. You can apply to a job immediately (once you have a CV).
A12: JS-02-09 | B12: Social sign up | C12: Leaving the completion step half-done does NOT create a usable account | D12: Negative | E12: High | F12: You reached the social completion step but have not confirmed yet. | G12: 1. Close the browser tab without confirming. 2. Open the site again and sign in with the same Google account. 3. Try to apply to a job. | H12: - | I12: The account is NOT Active. You are sent back to the completion step instead of into the site. You cannot apply to a job until the step is finished.
A13: JS-02-10 | B13: Social login | C13: Social login on an email that already has an account signs into THAT account | D13: Edge | E13: High | F13: An account already exists on name@gmail.com, created with email + password. | G13: 1. Sign out. 2. Open the Sign in page. 3. Click 'Google' and log in with the SAME address name@gmail.com. 4. Open My page and look at your CVs and applications. | H13: The Google account matching an existing email account | I13: You are signed into the EXISTING account — the same CVs and the same applications are there. A SECOND account is NOT created. Google now appears as a linked login method on My page.
A14: JS-02-11 | B14: Social login | C14: Cancelling at the provider brings you back without breaking anything | D14: Negative | E14: Medium | F14: You are logged out. | G14: 1. Click 'Facebook' on the Sign in page. 2. At Facebook, press Cancel / Deny. | H14: - | I14: You come back to the Saramin sign-in page. A short message explains the sign-in was cancelled. No half-made account is created.
A15: JS-02-12 | B15: Social login | C15: A provider that gives no email asks you for one | D15: Edge | E15: Medium | F15: You have a Facebook or GitHub account that does not release an email address. | G15: 1. Click that provider on the Sign up page. 2. Complete the provider login. | H15: - | I15: Because we cannot identify the account without an email, the site asks you to type an email and verify it before the account is created. No account is created on an unknown email.
... A20: JS-02-17 | B20: Social sign up | C20: Repeat the sign-up test on the other three providers | D20: Positive | E20: Medium | F20: You have unused Facebook, LinkedIn and GitHub accounts. | G20: 1. Repeat JS-03-02 to JS-03-08 using Facebook. 2. Repeat them using LinkedIn. 3. Repeat them using GitHub. | H20: One unused account per provider | I20: Every provider behaves the same way: verified email, locked email box, editable name, required phone, required Terms, Active with no verification email. Write in Notes which providers are actually switched on in this release.

Sheet JS-03 Sign in
A1: JS-03 · Sign in, password reset and account status
A2: Fill in only the yellow columns: Actual Result, Status, Tested By, Test Date, Notes / Bug ID. Status must be one of: Pass, Fail, Blocked, Not Run. If a step does not behave as written in 'Expected Result', mark Fail and write exactly what happened.
A3: Test Case ID | B3: Feature / Screen | C3: Test Case Title | D3: Type | E3: Priority | F3: Pre-condition | G3: Test Steps (do these in order) | H3: Test Data | I3: Expected Result (what you should see) | J3: Actual Result | K3: Status | L3: Tested By | M3: Test Date | N3: Notes / Bug ID
A4: JS-03-01 | B4: Sign in | C4: Sign in with the correct email and password | D4: Positive | E4: High | F4: An Active account exists and you know its password. | G4: 1. Open the Sign in page. 2. Type the email and password. 3. Click Sign in. | H4: A verified Active account | I4: You are signed in and your name / avatar appears in the header.
A5: JS-03-02 | B5: Sign in | C5: Wrong password shows a general message that does not reveal anything | D5: Negative | E5: High | F5: An Active account exists. | G5: 1. Open the Sign in page. 2. Type the correct email and a WRONG password. 3. Click Sign in. 4. Write down the exact message. | H5: Password: WrongPass99 | I5: You are not signed in. The message is general, for example 'email or password is incorrect'. It must NOT say the password is wrong or that the email exists.
A6: JS-03-03 | B6: Sign in | C6: Unknown email shows exactly the SAME message as a wrong password | D6: Negative | E6: High | F6: You know an email address that has no account. | G6: 1. Open the Sign in page. 2. Type an email that is not registered and any password. 3. Click Sign in. 4. Compare the message with the one you wrote down in JS-04-02. | H6: Email: nobody-here-9911@mail.com | I6: The message is WORD-FOR-WORD the same as in JS-04-02. If the two messages are different, someone could use the form to find out which emails are registered — mark this Fail.
A7: JS-03-04 | B7: Sign in | C7: 'Remember me' is off by default | D7: Positive | E7: Low | F7: You are logged out. | G7: 1. Open the Sign in page. 2. Look at the 'Remember me' tick box before touching anything. | H7: - | I7: 'Remember me' is NOT ticked when the page opens.
A8: JS-03-05 | B8: Sign in | C8: Too many wrong attempts locks sign-in for a while | D8: Edge | E8: High | F8: An Active account exists. Ask the team how many attempts are allowed before lockout. | G8: 1. Try to sign in with the wrong password, over and over (for example 10 times). 2. Then try the CORRECT password. | H8: - | I8: After the agreed number of failures, sign-in is blocked for a while with a clear message. Even the correct password is refused during the lockout window. After the window passes, the correct password works — the account is not blocked for ever.
A9: JS-03-06 | B9: Password reset | C9: Forgot password always gives the same answer, for any email | D9: Negative | E9: High | F9: You are on the Sign in page. | G9: 1. Click 'Forgot password'. 2. Type a REGISTERED email and submit. Write down the message. 3. Repeat with an email that is NOT registered. Write down the message. | H9: One registered email, one unknown email | I9: Both times the message is the same, for example 'if that email exists we have sent a link'. Different messages would let someone discover which emails are registered — that is a Fail.
A10: JS-03-07 | B10: Password reset | C10: The reset link works and lets you set a new password | D10: Positive | E10: High | F10: You asked for a reset on an email you can open. | G10: 1. Open the reset email. 2. Click the link. 3. Type a new password twice. 4. Save. 5. Sign in with the new password. | H10: New password: NewPass123 | I10: The password is changed and you can sign in with the new one. The old password no longer works.
A11: JS-03-08 | B11: Password reset | C11: Finishing a reset signs you out of every other device | D11: Edge | E11: High | F11: The same account is signed in on two browsers (for example Chrome and Firefox). | G11: 1. In browser A, complete a password reset (JS-04-07). 2. Go to browser B and refresh any page or click any menu. | H11: - | I11: Browser B is signed out and asks you to sign in again. This is on purpose: after a reset we assume the old password is not safe.
A12: JS-03-09 | B12: Password reset | C12: The reset link expires after 1 hour and cannot be used twice | D12: Edge | E12: Medium | F12: You have a reset link older than 1 hour, and a second link you already used. | G12: 1. Click the expired link. 2. Click the already-used link. | H12: - | I12: Both are refused with a clear message and a button to request a new link. Neither one lets you set a password.
A13: JS-03-10 | B13: Account status | C13: A Suspended account cannot sign in and is never told the internal reason | D13: Negative | E13: High | F13: Ask an Admin user to Suspend your test account (they must type a reason). | G13: 1. Try to sign in with that account. 2. Read the message carefully. | H13: - | I13: Sign-in is refused. The message gives a support contact. The reason the Admin typed is NOT shown anywhere to you — that text is internal only.
A14: JS-03-11 | B14: Account status | C14: Signing in to a Deactivated account inside the grace window offers to reactivate | D14: Edge | E14: High | F14: You deactivated a test account today (see the Deactivate sheet). | G14: 1. Try to sign in with that account. | H14: - | I14: You are NOT shown a plain error. You are offered 'reactivate your account'. Accepting brings the account back.
A15: JS-03-12 | B15: Sign in | C15: After signing in you go back to the page you were trying to reach | D15: Positive | E15: Medium | F15: You are logged out. | G15: 1. Open a job detail page directly. 2. Click 'Apply now'. 3. Sign in on the page that opens. | H15: - | I15: After sign-in you are returned to the SAME job and the apply flow continues. You do not land on the homepage having lost the job.
A16: JS-03-13 | B16: Sign out | C16: Sign out ends the session | D16: Positive | E16: Medium | F16: You are signed in. | G16: 1. Click Sign out. 2. Press the browser Back button. 3. Try to open My page. | H16: - | I16: You are signed out. Going Back does not give you access again — My page asks you to sign in.

Sheet JS-04 Onboarding
A1: JS-04 · Onboarding wizard (the 4 steps + matched jobs)
A2: Fill in only the yellow columns: Actual Result, Status, Tested By, Test Date, Notes / Bug ID. Status must be one of: Pass, Fail, Blocked, Not Run. If a step does not behave as written in 'Expected Result', mark Fail and write exactly what happened.
A3: Test Case ID | B3: Feature / Screen | C3: Test Case Title | D3: Type | E3: Priority | F3: Pre-condition | G3: Test Steps (do these in order) | H3: Test Data | I3: Expected Result (what you should see) | J3: Actual Result | K3: Status | L3: Tested By | M3: Test Date | N3: Notes / Bug ID
A4: JS-04-01 | B4: Onboarding | C4: The wizard opens by itself right after an email sign-up | D4: Positive | E4: High | F4: You just created an account with email + password. | G4: 1. Finish the sign-up. 2. Look at the screen you land on. | H4: - | I4: The onboarding wizard opens automatically at step 1 of 4. You did not have to look for it in a menu.
A5: JS-04-02 | B5: Onboarding | C5: The wizard also opens after a social sign-up | D5: Positive | E5: High | F5: You just finished the social completion step. | G5: 1. Finish the completion step. 2. Look at the screen you land on. | H5: - | I5: The same onboarding wizard opens at step 1 of 4.
A6: JS-04-03 | B6: Onboarding | C6: Step 1 asks what work you want: category, then role, then industry | D6: Positive | E6: High | F6: You are on step 1 of the wizard. | G6: 1. Open the 'Desired job category' list and pick one. 2. Open the 'Desired job role' box and look at the suggestions. 3. Pick a role. 4. Open 'Desired industry' and pick some. | H6: Category: IT / Software Role: Software Developer Industry: Banking, FMCG | I6: All three fields are on the SAME screen (not one field per screen). The role suggestions are narrowed by the category you picked first. Industry allows more than one choice.
A7: JS-04-04 | B7: Onboarding | C7: Desired industry accepts at most 3 choices | D7: Negative | E7: Medium | F7: You are on step 1. | G7: 1. Pick 3 industries. 2. Try to pick a 4th one. | H7: - | I7: The 4th choice is not allowed. The screen makes clear the limit is 3 (for example the remaining options become unclickable).
A8: JS-04-05 | B8: Onboarding | C8: Step 2 accepts at most 3 work locations, at province / city level | D8: Positive | E8: High | F8: You are on step 2. | G8: 1. Open the location list. 2. Pick 3 locations. 3. Try to pick a 4th. | H8: Ho Chi Minh, Ha Noi, Da Nang, then try Binh Duong | I8: The list is provinces / cities (not districts or streets). Three can be picked. The 4th is refused.
A9: JS-04-06 | B9: Onboarding | C9: Step 3 asks only for total years of experience and highest education | D9: Positive | E9: High | F9: You are on step 3. | G9: 1. Look at every field on this step. 2. Fill them in. | H9: Years: 5 Highest education: Bachelor | I9: Only two things are asked: total years of work experience, and highest education level. It does NOT ask for company names, job titles, school names or majors — those belong on the CV.
A10: JS-04-07 | B10: Onboarding | C10: Step 4 asks for the expected salary as a range in VND | D10: Positive | E10: High | F10: You are on step 4. | G10: 1. Fill in the expected salary. 2. Continue. | H10: Salary: 20,000,000 – 30,000,000 VND | I10: The salary is entered as a range in VND and is accepted.
A11: JS-04-08 | B11: Onboarding | C11: The job-count 'carrot' updates as you answer | D11: Positive | E11: Medium | F11: You are on step 1. | G11: 1. Write down the job count shown on step 1. 2. Answer step 1 and go to step 2. Write down the count. 3. Answer step 2 and go to step 3. Write down the count. | H11: - | I11: A live count is shown on each step, for example '12,231 jobs match so far'. The number changes between steps as your answers narrow it down.
A12: JS-04-09 | B12: Onboarding | C12: The last step shows matched jobs and each one can be saved | D12: Positive | E12: High | F12: You finished step 4. | G12: 1. Look at the results page. 2. Click the save (heart) icon on one job. 3. Go to My page → Saved jobs. | H12: - | I12: A full page of matched jobs is shown with a line like 'We found the best job postings based on the information you entered'. Each job can be saved. The job you saved appears in Saved jobs.
A13: JS-04-10 | B13: Onboarding | C13: The results page leads to My CVs | D13: Positive | E13: High | F13: You are on the onboarding results page. | G13: 1. Click 'Complete your CV and go apply →'. | H13: - | I13: You land on My CVs, where you can upload a PDF or build a Saramin CV.
A14: JS-04-11 | B14: Onboarding | C14: Any step can be skipped and the account still works | D14: Positive | E14: High | F14: You are on step 1 of a brand-new account. | G14: 1. Skip every step until the end. 2. Go to the homepage and search for a job. 3. Open a job and try to apply (with a CV already uploaded). | H14: - | I14: Skipping is allowed on every step. The account is usable: you can browse, save and apply. An incomplete profile is normal — it lowers ranking, it does not block anything.
A15: JS-04-12 | B15: Onboarding | C15: Answers are saved step by step, so leaving half-way keeps what you typed | D15: Edge | E15: High | F15: You are on step 2 of the wizard. | G15: 1. Answer step 1 and step 2. 2. Close the browser without finishing. 3. Sign in again and return to the wizard (or My page). | H15: - | I15: The answers from steps 1 and 2 are still there. Nothing you already typed is lost.
... A19: JS-04-16 | B19: Onboarding | C19: The answers appear afterwards in the profile | D19: Positive | E19: High | F19: You completed all four onboarding steps. | G19: 1. Go to My page (or My CVs → profile summary). 2. Compare the desired role, category, industry, location, salary, years and education with what you typed. | H19: - | I19: Every one of the seven onboarding answers is shown on the profile with the same value you entered. They are editable there.

Sheet JS-05 Create CV
A1: JS-05 · Create a CV — upload a file, or build a Saramin CV
A2: Fill in only the yellow columns: Actual Result, Status, Tested By, Test Date, Notes / Bug ID. Status must be one of: Pass, Fail, Blocked, Not Run. If a step does not behave as written in 'Expected Result', mark Fail and write exactly what happened.
A3: Test Case ID | B3: Feature / Screen | C3: Test Case Title | D3: Type | E3: Priority | F3: Pre-condition | G3: Test Steps (do these in order) | H3: Test Data | I3: Expected Result (what you should see) | J3: Actual Result | K3: Status | L3: Tested By | M3: Test Date | N3: Notes / Bug ID
A4: JS-05-01 | B4: Add a new CV | C4: '+ Add new CV' offers exactly two routes | D4: Positive | E4: High | F4: You are signed in with an Active account and are on My CVs. | G4: 1. Click '+ Add new CV'. 2. Look at the choices offered. | H4: - | I4: Two routes are offered: 'Upload a CV' (recommended, already selected) and 'Build / Create a Saramin CV'. No other route is offered.
A5: JS-05-02 | B5: Add a new CV | C5: The same Add-a-new-CV flow opens from inside Apply | D5: Positive | E5: High | F5: You are signed in and on a job detail page of an Open job. | G5: 1. Click 'Apply now'. 2. In section ① Your CV, click 'Add a new CV'. 3. Compare the screen with what you saw in JS-06-01. | H5: - | I5: Exactly the same Add-a-new-CV screen opens, with the same two routes. The two places must not look or behave differently.
A6: JS-05-03 | B6: Upload a CV | C6: Uploading a normal PDF saves it in one step | D6: Positive | E6: High | F6: You have a real CV in PDF, under 5MB, containing work experience and education. | G6: 1. Choose 'Upload a CV'. 2. Pick the PDF file. 3. Look at the preview shown. 4. Click 'Save my PDF'. 5. Go back to My CVs. | H6: A normal 1–2 page CV PDF | I6: The PDF preview is shown before saving. After saving, the CV appears in My CVs with a name (the file name by default) and a tag showing it is an uploaded PDF. It can be used to apply straight away.
A7: JS-05-04 | B7: Upload a CV | C7: The uploaded file is kept exactly as it was | D7: Positive | E7: High | F7: You uploaded a CV (JS-06-03). | G7: 1. In My CVs, open the ⋯ menu on that CV and click Download. 2. Open the downloaded file. 3. Compare it page by page with the file you uploaded. | H7: - | I7: The downloaded file is identical to the one you uploaded — same pages, same layout, nothing changed or re-rendered.
A8: JS-05-05 | B8: Upload a CV | C8: A file type that is not allowed is refused | D8: Negative | E8: High | F8: You have a .txt or .xlsx file on your computer. | G8: 1. Choose 'Upload a CV'. 2. Try to pick the .txt (or .xlsx) file. | H8: any .txt file | I8: The file is refused BEFORE it uploads. A clear message names which types are allowed (PDF, DOC, DOCX). Nothing is added to My CVs.
A9: JS-05-06 | B9: Upload a CV | C9: A file that is too big is refused with a clear message | D9: Negative | E9: High | F9: You have a PDF bigger than 5MB. | G9: 1. Choose 'Upload a CV'. 2. Pick the big file. | H9: a PDF over 5MB | I9: The upload is refused with a message saying the file is too large and stating the limit. It does not fail silently or hang.
A10: JS-05-07 | B10: Upload a CV | C10: A file with no work experience AND no education is refused as a CV | D10: Negative | E10: High | F10: You have a PDF that is a blank page, a photo, or a document unrelated to a CV. | G10: 1. Choose 'Upload a CV'. 2. Pick that file. 3. Save. | H10: a blank PDF or a photo saved as PDF | I10: The file is NOT accepted as a CV. The message explains why in plain words and offers a way forward: build a CV manually, or upload a clearer file. This is the only case where an upload is fully blocked.
A11: JS-05-08 | B11: Convert offer | C11: After saving an upload, you are OFFERED (not forced) to create a Saramin CV | D11: Positive | E11: High | F11: You have just saved an uploaded PDF. | G11: 1. Look at the screen straight after saving. | H11: - | I11: An offer appears: 'Also create a Saramin CV from it?' It is an offer, not a required step — there is a clear way to decline.
A12: JS-05-09 | B12: Convert offer | C12: Declining the offer still leaves a complete, usable CV | D12: Positive | E12: High | F12: The convert offer is on screen. | G12: 1. Decline the offer. 2. Go to My CVs. 3. Open a job and start an apply, and try to pick this CV. | H12: - | I12: The uploaded CV is in My CVs and can be selected when applying. Nothing is missing or marked as incomplete because you declined.
A13: JS-05-10 | B13: Convert offer | C13: The offer is asked once, then lives quietly on the CV card | D13: Edge | E13: Medium | F13: You declined the convert offer. | G13: 1. Refresh My CVs. 2. Sign out and sign back in. 3. Open My CVs again. 4. Open the ⋯ menu on that CV. | H13: - | I13: The offer does NOT pop up again and again. It is still available as a quiet action on the CV (for example inside the ⋯ menu).
A14: JS-05-11 | B14: CV compare | C14: Accepting the offer opens the compare screen with the PDF beside the structured CV | D14: Positive | E14: High | F14: You uploaded a PDF and accepted the convert offer. | G14: 1. Wait for the reading / extracting state to finish. 2. Look at the compare screen. | H14: - | I14: Your uploaded PDF is shown on the LEFT as a reference. The same information restructured as a Saramin CV is on the RIGHT as the main subject. You can read both at once.
A15: JS-05-12 | B15: CV compare | C15: Missing details are flagged in the right place and can be typed in | D15: Positive | E15: High | F15: You are on the compare screen and something was not read correctly (for example a date or a job title). | G15: 1. Find a flagged gap on the right side. 2. Read it off your own PDF on the left. 3. Type it into the empty box. 4. Save. | H15: - | I15: Each gap is flagged INSIDE the structure at the exact place it belongs, with an empty box to type into. What you type is saved.
... A31: JS-05-28 | B31: Create CV | C31: Creating a CV during Apply sends you back to the job | D31: Positive | E31: High | F31: You are signed in with NO CV. You are on an Open job detail page. | G31: 1. Click 'Apply now'. 2. Follow the route to create / upload a CV. 3. Finish the CV. | H31: - | I31: After finishing you are taken BACK to the apply screen for the same job, with the new CV already selected. You do not have to find the job again.

Sheet JS-06 Manage CV
A1: JS-06 · My CVs — which CV is searchable, visibility, delete, rename
A2: Fill in only the yellow columns: Actual Result, Status, Tested By, Test Date, Notes / Bug ID. Status must be one of: Pass, Fail, Blocked, Not Run. If a step does not behave as written in 'Expected Result', mark Fail and write exactly what happened.
A3: Test Case ID | B3: Feature / Screen | C3: Test Case Title | D3: Type | E3: Priority | F3: Pre-condition | G3: Test Steps (do these in order) | H3: Test Data | I3: Expected Result (what you should see) | J3: Actual Result | K3: Status | L3: Tested By | M3: Test Date | N3: Notes / Bug ID
A4: JS-06-01 | B4: My CVs | C4: My CVs opens with the profile summary above the CV list | D4: Positive | E4: High | F4: You are signed in with at least one CV and completed onboarding. | G4: 1. Go to My account → My CVs. 2. Read the top of the page. | H4: - | I4: A profile summary is shown first: name, visibility badge, contact, desired job / level / locations / industries / salary, experience, education, availability. Counters are shown too: proposals received, CV views, applications sent. The CV list is below it.
A5: JS-06-02 | B5: My CVs | C5: Each CV row shows its name and what kind of CV it is | D5: Positive | E5: High | F5: You have one uploaded PDF CV and one built Saramin CV. | G5: 1. Look at both rows in the CV list. | H5: - | I5: Each row shows the CV NAME (for example 'Product Designer CV') and a tag saying 'Uploaded PDF' or 'Saramin template'. Both are shown as the same kind of item, at the same level.
A6: JS-06-03 | B6: My CVs | C6: Only 'View as employer' is a direct link; everything else is behind the ⋯ menu | D6: Positive | E6: Medium | F6: You are on My CVs with at least one CV. | G6: 1. Look at the CV row. 2. Open the ⋯ button at the top-right of the row. | H6: - | I6: 'View as employer' is a text link under the CV name. Download, Rename, Delete (in red) and the 'Cho nhà tuyển dụng tìm thấy' switch are all inside the ⋯ menu. Delete is NOT sitting next to View where it could be clicked by mistake.
A7: JS-06-04 | B7: Searchable CV | C7: Turning the searchable switch ON for one CV turns it OFF for the others | D7: Positive | E7: High | F7: You have 2 or 3 CVs and CV A is currently the searchable one. | G7: 1. Note which CV shows the 'Đang hiển thị' badge. 2. Open the ⋯ menu on CV B and turn the searchable switch ON. 3. Look at both rows. | H7: - | I7: CV B becomes the searchable one and shows the 'Đang hiển thị' badge. CV A is switched off automatically. Exactly ONE CV is searchable at any time.
A8: JS-06-05 | B8: Searchable CV | C8: The helper line explains that other CVs can still be used to apply | D8: Positive | E8: Medium | F8: You have the ⋯ menu open on a CV. | G8: 1. Read the text under the searchable switch. | H8: - | I8: It says something equivalent to 'Chỉ 1 CV được tìm thấy. Các CV khác vẫn ứng tuyển được.' — only one CV is found by employers, the others can still be used to apply.
A9: JS-06-06 | B9: View as employer | C9: 'View as employer' shows what an employer would actually see | D9: Positive | E9: Medium | F9: You have a CV. | G9: 1. Click 'View as employer' on a CV row. | H9: - | I9: A preview opens showing the CV the way an employer sees it. There are no surprises about layout or which fields are visible.
A10: JS-06-07 | B10: Visibility | C10: Setting visibility to Hidden removes you from employer CV search immediately | D10: Positive | E10: High | F10: Your visibility is Discoverable. A tester with a Company account that has CV-search entitlement can search and find you. | G10: 1. Ask the company tester to search and confirm they can see your locked preview. Screenshot it. 2. Set your visibility to Hidden and confirm. 3. Ask the company tester to run the SAME search again straight away (no waiting, no re-index). | H10: - | I10: You disappear from the results immediately — including from the result COUNT, not just from the visible rows. If you are still counted or listed, mark Fail.
A11: JS-06-08 | B11: Visibility | C11: The confirmation says exactly what stops and what does not | D11: Positive | E11: High | F11: You are about to switch visibility to Hidden. | G11: 1. Click the visibility control. 2. Read the confirmation text before pressing confirm. | H11: - | I11: It states that employers can no longer discover you, AND that applications you already sent are NOT withdrawn. Both halves must be there — 'hide me' is easily misread as 'take everything back'.
A12: JS-06-09 | B12: Visibility | C12: Hidden does not affect applications already sent | D12: Edge | E12: High | F12: You applied to a job, then set visibility to Hidden. | G12: 1. Ask the company tester to open their applicant list for that job. | H12: - | I12: Your application is still on the employer's board with the CV attached. Hiding your profile does not pull back an application already delivered.
A13: JS-06-10 | B13: Unlock history | C13: You can see which companies unlocked your CV and when | D13: Positive | E13: Medium | F13: A company tester has spent an unlock on your CV. | G13: 1. Go to My CVs. 2. Open the unlock history. | H13: - | I13: The company name and the date / time of the unlock are listed. The list is read-only.
A14: JS-06-11 | B14: Delete CV | C14: Deleting a CV asks you to confirm and explains what it does NOT do | D14: Negative | E14: High | F14: You have 2 CVs and have applied to a job with one of them. | G14: 1. Open ⋯ on the CV you applied with. 2. Click Delete. 3. Read the confirmation. 4. Confirm. 5. Go to My applications and open that application. | H14: - | I14: The confirmation explains that CVs already sent with applications are NOT withdrawn. After deleting, the old application still opens and still shows the CV that was sent.
A15: JS-06-12 | B15: Delete CV | C15: Deleting your LAST CV warns you that quick apply will stop working | D15: Edge | E15: Medium | F15: You have exactly one CV. | G15: 1. Delete it. 2. Read the warning. 3. Confirm. 4. Open a job and click Apply. | H15: - | I15: The warning says quick apply will stop working until you add another CV. Deleting is still allowed. Applying now routes you to create a CV first.
... A20: JS-06-17 | B20: Completeness | C20: Completeness names one clear next action, not just a number | D20: Positive | E20: Medium | F20: You have a partly filled CV. | G20: 1. Look at the completeness area on My CVs / My page. | H20: - | I20: As well as a percentage, ONE specific next action is named, for example 'add your desired salary'. A bare percentage with nothing to act on is a Fail.

Sheet JS-07 Find jobs
A1: JS-07 · Homepage, search results and job detail (jobseeker side)
A2: Fill in only the yellow columns: Actual Result, Status, Tested By, Test Date, Notes / Bug ID. Status must be one of: Pass, Fail, Blocked, Not Run. If a step does not behave as written in 'Expected Result', mark Fail and write exactly what happened.
A3: Test Case ID | B3: Feature / Screen | C3: Test Case Title | D3: Type | E3: Priority | F3: Pre-condition | G3: Test Steps (do these in order) | H3: Test Data | I3: Expected Result (what you should see) | J3: Actual Result | K3: Status | L3: Tested By | M3: Test Date | N3: Notes / Bug ID
A4: JS-07-01 | B4: Homepage | C4: The homepage shows every section it is supposed to | D4: Positive | E4: High | F4: Open jobs exist on the platform. You are logged out. | G4: 1. Open the Jobseeker homepage. 2. Scroll down through the whole page. 3. List every section you see. | H4: - | I4: You can see: the hero search (keyword + location + a search button), quick category chips, a Hot jobs rail, a Top companies block, and the banner slots managed by Admin.
A5: JS-07-02 | B5: Homepage | C5: Only jobs that are Open AND Exposure On are shown | D5: Positive | E5: High | F5: Ask an Admin tester to prepare 4 jobs on the same company: one Draft, one Scheduled for tomorrow, one Open with Exposure On, one Closed. | G5: 1. Open the homepage. 2. Search for each of the 4 job titles. | H5: 4 jobs in 4 different states | I5: Only the Open + Exposure On job can be found. The Draft, the Scheduled and the Closed jobs are nowhere on the homepage or in search.
A6: JS-07-03 | B6: Homepage | C6: Turning Exposure Off hides a live job everywhere, without closing it | D6: Edge | E6: High | F6: An Open job with Exposure On is visible on the jobseeker site. | G6: 1. Find the job in search and screenshot it. 2. Ask the Admin (or company) tester to switch Exposure to Off. 3. Refresh the homepage and search again. 4. Also open the job's direct URL. 5. Ask the tester to check the job's STATUS in Admin. | H6: - | I6: The job disappears from the homepage and from search. The direct URL no longer shows an applyable job. In Admin the status is still 'Open' — only Exposure changed.
A7: JS-07-04 | B7: Homepage | C7: Turning Exposure back On makes the job visible again | D7: Positive | E7: High | F7: The job from JS-08-03 is currently hidden. | G7: 1. Ask the tester to switch Exposure back to On. 2. Refresh the jobseeker search. | H7: - | I7: The job appears again in search and can be applied to.
A8: JS-07-05 | B8: Homepage | C8: Boosted / higher-tier jobs rank first in the Hot jobs rail | D8: Positive | E8: Medium | F8: Two jobs exist in the same category: one on a Top Job / Distinction product, one on Basic. | G8: 1. Open the homepage. 2. Look at the order of jobs in the Hot jobs rail. | H8: - | I8: The higher-tier (boosted) job appears above the Basic one. Write in Notes exactly what 'Hot' is driven by in this build (boost / recency / clicks) — the team has an open question here.
A9: JS-07-06 | B9: Homepage | C9: A signed-in user sees personalised rails | D9: Positive | E9: Medium | F9: You have an account with onboarding preferences set (for example IT in Ho Chi Minh). | G9: 1. Look at the homepage while logged out and note the jobs. 2. Sign in. 3. Look at the homepage again. | H9: - | I9: When signed in, the rails lean towards your saved preferences. When logged out, a popular / general fallback is shown instead — the page is never empty.
A10: JS-07-07 | B10: Search | C10: The hero search takes you to the results page with your keyword and location | D10: Positive | E10: High | F10: You are on the homepage. | G10: 1. Type a keyword in the hero search. 2. Pick a location. 3. Press the search button. | H10: Keyword: Developer Location: Ho Chi Minh | I10: You land on the search results page. The keyword and the location are already applied as filters and are visible on screen.
A11: JS-07-08 | B11: Search | C11: Every filter narrows the results | D11: Positive | E11: High | F11: You are on the search results page with results showing. | G11: 1. Write down the number of results. 2. Apply a Location filter. Write down the number. 3. Apply an Industry / Category filter. Write down the number. 4. Apply a Salary range. Write down the number. 5. Apply Level, then Experience, then Employment type. | H11: - | I11: Each filter reduces (or keeps) the result count and the visible jobs really do match the filter. Counts are shown next to the facet options.
A12: JS-07-09 | B12: Search | C12: Filters are in the web address, so the link can be shared and Back works | D12: Positive | E12: High | F12: You are on the search results page. | G12: 1. Apply 2 filters. 2. Copy the URL from the address bar. 3. Open it in a new browser tab. 4. Go back to the first tab and press the browser Back button. | H12: - | I12: The new tab opens with exactly the same filters applied. The Back button removes the last filter instead of leaving the page or losing everything.
A13: JS-07-10 | B13: Search | C13: Sorting works and 'Thỏa thuận' salaries do not jump to the top | D13: Positive | E13: Medium | F13: Search results include some jobs with a salary range and some marked 'Thỏa thuận' (negotiable). | G13: 1. Sort by Newest — check the posted dates. 2. Sort by Salary — look at where the 'Thỏa thuận' jobs land. 3. Sort by Relevance. | H13: - | I13: Newest really is newest first. With Salary sort, the 'Thỏa thuận' jobs are unranked / last — they never appear as the highest paid.
A14: JS-07-11 | B14: Search | C14: You can save a job from the result card without leaving the page | D14: Positive | E14: Medium | F14: You are signed in and on the search results page. | G14: 1. Click the heart / save icon on a result card. 2. Check the page did not navigate away. 3. Go to My page → Saved jobs. | H14: - | I14: The card shows as saved and the page does not reload or navigate. The job is listed in Saved jobs.
A15: JS-07-12 | B15: Search | C15: No results is explained, not shown as an empty broken page | D15: Negative | E15: Medium | F15: You are on the search results page. | G15: 1. Type a keyword that matches nothing, for example 'qqqzzzxx'. 2. Search. | H15: Keyword: qqqzzzxx | I15: A friendly message says nothing was found and suggests how to broaden the search. The page is not blank and does not show an error.
... A24: JS-07-21 | B24: Job detail | C24: Opening a job counts a view (but not endlessly) | D24: Edge | E24: Low | F24: You have an Admin tester who can read the job's view count. | G24: 1. Ask the tester to note the current view count. 2. Open the job detail once. 3. Refresh the same page 5 times quickly. 4. Ask the tester to check the count again. | H24: - | I24: The view count goes up. It does not go up by 6 — repeated refreshes by the same person are de-duplicated.

Sheet JS-08 Apply to a job
A1: JS-08 · Apply flow
A2: Fill in only the yellow columns: Actual Result, Status, Tested By, Test Date, Notes / Bug ID. Status must be one of: Pass, Fail, Blocked, Not Run. If a step does not behave as written in 'Expected Result', mark Fail and write exactly what happened.
A3: Test Case ID | B3: Feature / Screen | C3: Test Case Title | D3: Type | E3: Priority | F3: Pre-condition | G3: Test Steps (do these in order) | H3: Test Data | I3: Expected Result (what you should see) | J3: Actual Result | K3: Status | L3: Tested By | M3: Test Date | N3: Notes / Bug ID
A4: JS-08-01 | B4: Apply flow | C4: Apply opens as one screen over the job, with the job echoed back | D4: Positive | E4: High | F4: You are signed in, Active, with at least one CV. You are on an Open job. | G4: 1. Click 'Apply now'. 2. Look at the top of the apply screen. | H4: - | I4: The apply screen opens over the job. It shows the job title, company, location and deadline so you are sure what you are applying to.
A5: JS-08-02 | B5: Apply flow | C5: Section ① lists your CVs and pre-selects the searchable / primary one | D5: Positive | E5: High | F5: You have 2 or 3 CVs, one of them marked as the searchable / primary CV. | G5: 1. Open the apply screen. 2. Look at section ① Your CV. | H5: - | I5: All your CVs are listed as a radio list, each with its name and kind (Saramin CV / uploaded file) and last-updated date. The primary one is already selected. There is an 'Add a new CV' option.
A6: JS-08-03 | B6: Apply flow | C6: Section ② arrives pre-filled from your profile | D6: Positive | E6: High | F6: You completed sign-up and onboarding. | G6: 1. Open the apply screen. 2. Look at section ② Application information. | H6: - | I6: Full name, contact email, phone, location, years of experience and highest education are already filled in from your profile. You are confirming, not typing everything again.
A7: JS-08-04 | B7: Apply flow | C7: A social login's email is locked but the contact email can be changed | D7: Positive | E7: High | F7: You are signed in with an account created through Google. | G7: 1. Open the apply screen. 2. Look at the email fields in section ②. 3. Change the CONTACT email to a different address. 4. Submit the application. 5. Ask the company tester which email they received. | H7: Contact email: work.address@mail.com | I7: The login email is shown locked with 'Google' named beside it and cannot be edited. The contact email CAN be edited. The employer receives the CONTACT email you typed, not the Google one.
A8: JS-08-05 | B8: Apply flow | C8: An application cannot be sent with an empty phone number | D8: Negative | E8: High | F8: You are on the apply screen. | G8: 1. Clear the Phone box. 2. Fill everything else in. 3. Tick consent. 4. Click 'Submit application'. 5. Ask a developer to send the same request with an empty phone directly to the API. | H8: Phone: (empty) | I8: The screen refuses to submit and asks for the phone. The API ALSO refuses — the check is not only in the browser.
A9: JS-08-06 | B9: Apply flow | C9: Section ③ Desired job is pre-filled from onboarding | D9: Positive | E9: High | F9: You answered the onboarding wizard. | G9: 1. Open the apply screen. 2. Look at section ③ Desired job. | H9: - | I9: Desired location, level, industry, field, expected salary and availability are pre-filled with your onboarding answers.
A10: JS-08-07 | B10: Apply flow | C10: The cover message is optional and limited to 1,000 characters | D10: Negative | E10: Medium | F10: You are on the apply screen. | G10: 1. Leave the cover message empty and check you can still submit. 2. Start again and paste more than 1,000 characters into it. | H10: A text longer than 1,000 characters | I10: The application can be sent with no cover message. Text longer than 1,000 characters is refused or cut at the limit, with the limit shown.
A11: JS-08-08 | B11: Apply flow | C11: The consent tick box is required | D11: Negative | E11: High | F11: You are on the apply screen with everything filled in. | G11: 1. Do NOT tick the consent box ('I agree to share my profile & CV with this employer'). 2. Click Submit. | H11: - | I11: The application is not sent. The screen asks you to accept the consent first.
A12: JS-08-09 | B12: Apply flow | C12: A complete application is submitted and appears in My applications | D12: Positive | E12: High | F12: You are on the apply screen with everything filled in and consent ticked. | G12: 1. Click 'Submit application'. 2. Look at the confirmation. 3. Go to My applications. | H12: - | I12: The application is created. You land on a confirmation that links to My applications. The application is listed there with today's date, the job, the company and the CV you used.
A13: JS-08-10 | B13: Apply flow | C13: The employer receives the application straight away | D13: Positive | E13: High | F13: You just submitted an application (JS-09-09). A tester has the company account for that job. | G13: 1. Ask the company tester to open Recruiting → Applicants for that job. 2. Ask them to open your card. | H13: - | I13: Your application is on their board immediately, in the first stage ('New'). They can see your CV, name, contact email and phone. There is no waiting period where the application exists but the employer cannot see it.
