Workbook

Sheet How to review
B2: Company & Job fields — for client review
B3: Saramin Vietnam · admin (HQ) screens · field list taken from the working mockup
B5: What to do
B6: • | C6: Two tabs to go through: Company fields and Job fields.
B7: • | C7: For each row, fill the yellow KEEP? column — Keep · Keep – change it · Remove · Decide later.
B8: • | C8: Put anything to discuss in Client comment. Rows marked "OPEN QUESTION" in Rule / note are the ones we need a decision on.
B9: • | C9: Grey rows are system-generated or derived: nothing to decide, they are listed so the picture is complete.
B10: • | C10: Pink rows are the legally sensitive demographic fields on the job ad — please decide these explicitly.
B12: Colour key
C13: You fill this in
C14: System-generated / derived — nothing to decide
C15: Legally sensitive — needs an explicit decision
B17: Where the review stands
C18: Company | D18: Job | E18: Total
B19: Fields in total | C19: =COUNT('Company fields'!$A$5:$A$42) | D19: =COUNT('Job fields'!$A$5:$A$46) | E19: =C19+D19
B20: Required today | C20: =COUNTIF('Company fields'!$F$5:$F$42,"Yes*") | D20: =COUNTIF('Job fields'!$F$5:$F$46,"Yes*") | E20: =C20+D20
B21: Marked Keep | C21: =COUNTIF('Company fields'!$J$5:$J$42,"Keep") | D21: =COUNTIF('Job fields'!$J$5:$J$46,"Keep") | E21: =C21+D21
B22: Marked Keep – change it | C22: =COUNTIF('Company fields'!$J$5:$J$42,"Keep – change it") | D22: =COUNTIF('Job fields'!$J$5:$J$46,"Keep – change it") | E22: =C22+D22
B23: Marked Remove | C23: =COUNTIF('Company fields'!$J$5:$J$42,"Remove") | D23: =COUNTIF('Job fields'!$J$5:$J$46,"Remove") | E23: =C23+D23
B24: Not answered yet | C24: =C19-C21-C22-C23 | D24: =D19-D21-D22-D23 | E24: =C24+D24
B25: Open questions to answer | C25: =COUNTIF('Company fields'!$I$5:$I$42,"*OPEN QUESTION*")+COUNTIF('Company fields'!$I$5:$I$42,"*CONFIRM*") | D25: =COUNTIF('Job fields'!$I$5:$I$46,"*OPEN QUESTION*")+COUNTIF('Job fields'!$I$5:$I$46,"*CONFIRM*") | E25: =C25+D25
B27: Counts are live formulas — they update as the KEEP? column is filled in. "Required today" counts what the current mockup enforces, not what it should enforce; the rows flagged OPEN QUESTION are exactly where those two differ.

Sheet Company fields
A1: Company fields
A2: Source: the New-company form and the Company detail “Basic info — from CRM” card in the admin mockup.
A4: # | B4: Section | C4: Field (label in the screen) | D4: Vietnamese / alt label | E4: Input type | F4: Required? | G4: Values come from | H4: Where it appears | I4: Rule / note | J4: KEEP? | K4: Client comment
A5: IDENTITY
A6: 1 | B6: Identity | C6: Company ID | D6: Mã công ty | E6: Auto text — CO-XXXXXXX | F6: System | G6: System | H6: Create (on save) · Detail · List search | I6: Assigned on save, never typed, never changes for the life of the company. Capacity ~1.07 billion. Not guessable.
A7: 2 | B7: Identity | C7: Legal name | D7: Tên pháp lý | E7: Text | F7: Yes | G7: User input | H7: Create · Detail · List | I7: As written on the tax registration. The only hard-required company field today.
A8: 3 | B8: Identity | C8: Short name | D8: Tên viết tắt / thương hiệu | E8: Text | F8: No | G8: User input | H8: Create · Detail · List · Pipeline | I8: Display name everywhere. When empty the system falls back to the legal name. Two companies may share one.
A9: 4 | B9: Identity | C9: Tax code (MST) | D9: Mã số thuế | E9: Text | F9: No | G9: User input | H9: Create · Detail | I9: OPEN QUESTION for the client: not required in the mockup, but duplicate detection and every invoice depend on it. Rule built: only an identical FULL MST blocks; a shared 10-digit root is treated as a branch and offered as a link.
A10: 5 | B10: Identity | C10: Công ty mẹ | D10: Công ty mẹ (tuỳ chọn) | E10: Searchable select — company | F10: No | G10: Existing companies | H10: Create · Detail | I10: The DIRECT parent only, any depth. Empty = standalone or group root. Nothing is inherited down the tree (own MST, quota, billing, sales owner). Cycles are rejected.
A11: CLASSIFICATION
A12: 6 | B12: Classification | C12: Industry | D12: Ngành nghề | E12: Select | F12: No | G12: Master data → Industry | H12: Create · Detail · List filter | I12: Its own field — not joined to company size.
A13: 7 | B13: Classification | C13: Company size | D13: Quy mô nhân sự | E13: Select — band | F13: No | G13: Master data → Size bands | H13: Create · Detail | I13: Bands: 1–9 / 10–49 / 50–200 / 200–500 / 500–1000 / 1000–5000 / 5000+.
A14: 8 | B14: Classification | C14: Company tags | D14: Nhãn | E14: Multi-select chips | F14: No | G14: Master data → Tags | H14: Create · Detail | I14: Editorial labels, many per company (e.g. "Korean company", "Key account").
A15: LOCATION
A16: 9 | B16: Location | C16: Quốc tịch / Country | D16: Quốc tịch công ty | E16: Searchable select | F16: No | G16: Master data → Country | H16: Create · Detail | I16: Where the company is REGISTERED. This is what decides whether the Vietnamese province picker appears. OPEN QUESTION: should it be mandatory, since it drives the field below?
A17: 10 | B17: Location | C17: Tỉnh / Thành phố · City | D17: Tỉnh / Thành phố | E17: Select — province | F17: Conditional | G17: Master data → Locations | H17: Create · Detail · List filter | I17: Shown ONLY when country = Việt Nam. For a foreign company the city goes in Address instead.
A18: 11 | B18: Location | C18: Address | D18: Địa chỉ | E18: Text | F18: Yes (by rule) | G18: User input | H18: Create · Detail · Documents | I18: Full head-office address, asked for every country — it prints on quotations, POs and invoices. The rule says required; the mockup does not yet star it.
A19: 12 | B19: Location | C19: Website | D19: Website | E19: Text | F19: No | G19: User input | H19: Create · Detail · Company page | I19: Sits after Address: the two are read together as "where they are".
A20: PRIMARY CONTACT
A21: 13 | B21: Primary contact | C21: Contact name | D21: Họ và tên người liên hệ | E21: Text | F21: Yes | G21: User input | H21: Create → becomes the first row on the Contacts tab | I21: The create form asks for ONE contact to get started. After creation, contacts are managed on the Contacts tab, which holds any number of them — so these four fields are no longer repeated on Basic info.
A22: 14 | B22: Primary contact | C22: Title | D22: Chức danh | E22: Select or free text | F22: No | G22: Master data → Titles (typeable) | H22: Create · Contacts tab
A23: 15 | B23: Primary contact | C23: Phone | D23: Điện thoại | E23: Text | F23: No | G23: User input | H23: Create · Contacts tab | I23: OPEN QUESTION: should at least one of phone / email be mandatory? A contact with neither cannot be contacted.
A24: 16 | B24: Primary contact | C24: Email | D24: Email | E24: Text | F24: No | G24: User input | H24: Create · Contacts tab | I24: Same question as Phone.
A25: SALES
A26: 17 | B26: Sales | C26: Lead source | D26: Nguồn khách hàng | E26: Select or free text | F26: No | G26: Master data → Lead source | H26: Create · Detail · Reports | I26: Website sign-up / Inbound call / Referral / Event – job fair / Outbound / Partner.
A27: 18 | B27: Sales | C27: Sales owner | D27: Sales phụ trách | E27: Select — user | F27: No | G27: Admin users | H27: Create · Detail · List · Pipeline · KPI | I27: Drives "my customers", the Sales vs Sales-lead views and every KPI number. OPEN QUESTION: should it default to the creator and be mandatory?
A28: 19 | B28: Sales | C28: Products interested | D28: Sản phẩm quan tâm | E28: Checkboxes | F28: No | G28: Products module | H28: Create · Detail | I28: Pre-sale INTENT (Job Posting / Resume Search). What they actually BOUGHT is a different fact, on the Products & billing tab.
A29: 20 | B29: Sales | C29: Estimated deal value | D29: Giá trị dự kiến (₫) | E29: Number — ₫ | F29: No | G29: User input | H29: Create · Detail · Pipeline card | I29: The rep's own estimate, used for the pipeline total until a quotation exists; the quotation total then supersedes it.
A30: 21 | B30: Sales | C30: Description | D30: Ghi chú | E30: Long text | F30: No | G30: User input | H30: Create · Detail | I30: How we heard about them, their need, the next step.
A31: 22 | B31: Sales | C31: Next step | D31: Bước tiếp theo | E31: Text | F31: No | G31: User input | H31: Detail · List | I31: Entered after creation, not on the create form. What the rep will do next.
A32: SYSTEM / DERIVED
A33: 23 | B33: System / derived | C33: Customer status | D33: Trạng thái khách hàng | E33: Badge — 3 values | F33: n/a | G33: Derived | H33: Detail · List filter | I33: New (never bought) / Existing (paid at least once) / Churn (no new order for 12 months). Computed from invoices — never typed.
A34: 24 | B34: System / derived | C34: Pipeline stage | D34: Giai đoạn bán hàng | E34: Badge — 6 values | F34: n/a | G34: Derived from the deal | H34: Pipeline · Detail | I34: Proposal / Qualified / Negotiation / PO / Invoice / Lost. Lives on the DEAL, not on the company.
A35: 25 | B35: System / derived | C35: Membership tier | D35: Hạng thành viên | E35: Badge | F35: n/a | G35: Derived from revenue | H35: Detail · List | I35: Pure arithmetic on 12-month revenue — no manual override.
A36: 26 | B36: System / derived | C36: Idle | D36: Số ngày không liên hệ | E36: Number — days | F36: n/a | G36: Derived | H36: Detail · List | I36: Days since the last SALES contact. Amber/red thresholds depend on the expected contact cadence. Independent of the pipeline stage.
A37: 27 | B37: System / derived | C37: Last PO date | D37: Ngày PO gần nhất | E37: Date | F37: n/a | G37: Derived from documents | H37: Detail · List
A38: 28 | B38: System / derived | C38: Renewal date | D38: Ngày gia hạn | E38: Date | F38: n/a | G38: Derived from the package | H38: Detail · List
A39: 29 | B39: System / derived | C39: Revenue (12 months) | D39: Doanh thu 12 tháng | E39: Number — ₫ | F39: n/a | G39: Derived from invoices | H39: Detail · List · KPI
A40: 30 | B40: System / derived | C40: Quota remaining | D40: Quota còn lại | E40: Number | F40: n/a | G40: Derived from purchases | H40: Detail → Products & billing | I40: Job postings left and CV unlocks left, per purchased package.
A41: 31 | B41: System / derived | C41: Company page exists | D41: Có trang công ty | E41: Yes / No | F41: n/a | G41: Derived | H41: Detail → Company page tab
...

Sheet Job fields
A1: Job fields
A2: Source: the Create-job form and the Job list columns in the admin mockup.
A4: # | B4: Section | C4: Field (label in the screen) | D4: Vietnamese / alt label | E4: Input type | F4: Required? | G4: Values come from | H4: Where it appears | I4: Rule / note | J4: KEEP? | K4: Client comment
A5: POSTING SETUP
A6: 1 | B6: Posting setup | C6: Company | D6: Công ty | E6: Searchable select | F6: Yes | G6: Existing companies | H6: Create · List | I6: Searchable by company name or Company ID. "Create company" is available inline if it does not exist yet.
A7: 2 | B7: Posting setup | C7: Package | D7: Gói tin | E7: Select | F7: No | G7: Products / Packages module | H7: Create · Detail | I7: Decides the duration and the exposure the ad gets. Free package shown expiring in 14 days.
A8: 3 | B8: Posting setup | C8: Exposure | D8: Hiển thị | E8: Toggle On / Off | F8: No | G8: User input | H8: Create · List | I8: Off hides the ad from the jobseeker site. Reversible before the deadline and does NOT close the job.
A9: JOB INFORMATION
A10: 4 | B10: Job information | C10: Job title (VI) | D10: Tiêu đề tin (Tiếng Việt) | E10: Text | F10: Yes | G10: User input | H10: Create · List · Jobseeker site | I10: Vietnamese is the default and required language, and the fallback shown wherever a translation is missing.
A11: 5 | B11: Job information | C11: Job title (EN) | D11: Tiêu đề tin (English) | E11: Text | F11: No | G11: User input | H11: Create · Jobseeker site | I11: The mockup shows VI / EN tabs. The written rule also names Korean — CONFIRM which languages are in scope.
A12: 6 | B12: Job information | C12: Job category | D12: Ngành / Nhóm nghề | E12: Select | F12: Yes | G12: Master data → Category | H12: Create · List · Search filter | I12: Also decides which Job roles can be picked below.
A13: 7 | B13: Job information | C13: Job role | D13: Vị trí công việc | E13: Multi-select chips | F13: Yes | G13: Master data → Role (by category) | H13: Create · Search filter | I13: Roles come from the selected category. A new one can be typed in.
A14: 8 | B14: Job information | C14: Job level | D14: Cấp bậc | E14: Select | F14: Yes | G14: Master data → Level | H14: Create · Search filter | I14: Intern/Student · Fresher/Entry · Experienced (non-manager) · Manager · Director and above.
A15: 9 | B15: Job information | C15: Job type | D15: Loại hình công việc | E15: Select | F15: Yes | G15: Master data → Job type | H15: Create · Search filter | I15: Full-time · Part-time · Internship · Online · Freelancer · Seasonal · Other.
A16: 10 | B16: Job information | C16: Industry | D16: Lĩnh vực công ty | E16: Select | F16: Yes | G16: Master data → Industry | H16: Create · Search filter | I16: OPEN QUESTION: the company record already has an industry. Should this be inherited from the company instead of re-asked on every job?
A17: 11 | B17: Job information | C17: Skill | D17: Kỹ năng | E17: Multi-select chips | F17: No | G17: Master data → Skill (typeable) | H17: Create · Search filter
A18: 12 | B18: Job information | C18: Working location — province / city | D18: Địa điểm làm việc | E18: Select — province | F18: Yes | G18: Master data → Locations | H18: Create · List · Search filter | I18: Up to 3 locations per job. Each location is a province/city + a street address.
A19: 13 | B19: Job information | C19: Working location — address | D19: Địa chỉ cụ thể | E19: Text | F19: Yes | G19: User input | H19: Create · Jobseeker site | I19: One per location row. Defaults can come from the company address.
A20: 14 | B20: Job information | C20: Salary from | D20: Lương từ | E20: Number | F20: Yes | G20: User input | H20: Create · Jobseeker site
A21: 15 | B21: Job information | C21: Salary to | D21: Lương đến | E21: Number | F21: Yes | G21: User input | H21: Create · Jobseeker site
A22: 16 | B22: Job information | C22: Salary currency | D22: Đơn vị tiền | E22: Select | F22: Yes | G22: Master data → Currency | H22: Create · Jobseeker site | I22: USD · VND · JPY · CNY · EUR · INR · GBP · RUB · SGD.
A23: 17 | B23: Job information | C23: Salary — show on the ad | D23: Hiển thị lương | E23: Toggle Show / Hide | F23: No | G23: User input | H23: Create · Jobseeker site | I23: Entered either way; this only controls whether jobseekers see the number. CONFIRM the salary-display policy.
A24: 18 | B24: Job information | C24: Number of headcount | D24: Số lượng cần tuyển | E24: Stepper — number | F24: No | G24: User input | H24: Create · Jobseeker site | I24: Has its own show/hide toggle, off by default.
A25: 19 | B25: Job information | C25: Application deadline | D25: Hạn nhận hồ sơ | E25: Date | F25: Yes | G25: User input | H25: Create · List · Jobseeker site | I25: When it passes, the job closes.
A26: JOB CONTENT
A27: 20 | B27: Job content | C27: Job description | D27: Mô tả công việc | E27: Rich text — VI + EN | F27: Yes | G27: User input | H27: Create · Jobseeker site
A28: 21 | B28: Job content | C28: Requirements | D28: Yêu cầu ứng viên | E28: Rich text — VI + EN | F28: Yes | G28: User input | H28: Create · Jobseeker site
A29: 22 | B29: Job content | C29: Benefits | D29: Phúc lợi | E29: Rich text — VI + EN | F29: No | G29: User input | H29: Create · Jobseeker site
A30: CANDIDATE EXPECTATION
A31: 23 | B31: Candidate expectation | C31: Minimum years of experience | D31: Số năm kinh nghiệm tối thiểu | E31: Stepper — number | F31: No | G31: User input | H31: Create · Search filter
A32: 24 | B32: Candidate expectation | C32: Minimum education level | D32: Trình độ học vấn tối thiểu | E32: Select | F32: No | G32: Master data → Education | H32: Create · Search filter | I32: High school · Associate's · College · Bachelor · Master · Doctorate · Others.
A33: 25 | B33: Candidate expectation | C33: Nationality | D33: Quốc tịch ứng viên | E33: Radio — Any / Vietnamese / Foreigner | F33: No | G33: Fixed list | H33: Create · Jobseeker site | I33: LEGALLY SENSITIVE for a Vietnamese job ad. Decide whether to collect it at all, and whether to display it.
A34: 26 | B34: Candidate expectation | C34: Gender | D34: Giới tính | E34: Radio — Any / Male / Female | F34: No | G34: Fixed list | H34: Create · Jobseeker site | I34: LEGALLY SENSITIVE — same decision.
A35: 27 | B35: Candidate expectation | C35: Marital status | D35: Tình trạng hôn nhân | E35: Radio — Any / Single / Married | F35: No | G35: Fixed list | H35: Create · Jobseeker site | I35: LEGALLY SENSITIVE — same decision. Recommend dropping it: it is the hardest of the four to justify.
A36: 28 | B36: Candidate expectation | C36: Age preference (from – to) | D36: Độ tuổi | E36: Number range + show toggle | F36: No | G36: User input | H36: Create · Jobseeker site | I36: LEGALLY SENSITIVE — same decision. Show toggle is off by default.
A37: 29 | B37: Candidate expectation | C37: Cover letter required? | D37: Yêu cầu thư giới thiệu | E37: Radio — 3 options | F37: No | G37: Fixed list | H37: Create · Apply flow | I37: Always required / optional / never required. Changes what the jobseeker must upload to apply.
A38: INTERNAL (HQ ONLY)
A39: 30 | B39: Internal (HQ only) | C39: Internal notes | D39: Ghi chú nội bộ | E39: Long text | F39: No | G39: User input | H39: Create · Detail | I39: Approval context, special instructions, follow-ups. Never shown publicly.
A40: SYSTEM / DERIVED
A41: 31 | B41: System / derived | C41: Job ID | D41: Mã tin | E41: Auto text | F41: n/a | G41: System | H41: Detail · List | I41: Assigned on save.
...
